Workbook

Sheet 多维度数据透视分析
A1: 行标签 | B1: 计数项:学员 ID | C1: 求和项:首次缴费 | D1: 求和项:总续费金额 | E1: 平均值项:学员生命周期价值 (LTV) | H1: Scratch 学员基数最大，累计营收贡献最高，是核心营收课程； Python 课程平均 LTV 最高，续费率超 100%，学员长期价值最高，可重点推广； C++ 课程续费率偏低，可优化课后服务、赛事运营提升留存。
A2: c++ | B2: 6 | C2: 11000 | D2: 7800 | E2: 3133.3333
A3: Python | B3: 5 | C3: 8400 | D3: 9600 | E3: 3600
A4: scratch | B4: 21 | C4: 33800 | D4: 44400 | E4: 3723.8095
A5: 总计 | B5: 32 | C5: 53200 | D5: 61800 | E5: 3593.75
A23: 行标签 | B23: 求和项:当月新签营收 | C23: 求和项:当月实收续费 | D23: 求和项:月度总营收
A24: 2025 | B24: 53200 | C24: 57000 | D24: 110200 | H24: 2025 年 7-8 月暑期新签营收同比 2024 年增长显著，是全年招生旺季，投放预算应向暑期倾斜； 2025 年 1-3 月报名学员的续费营收，同比 2024 年同批次学员增长明显，获客质量显著提升，是优质招生时段； 月度营收整体呈上升趋势，业务增长动力充足，续费营收占比逐步提升，业务健康度向好。
A25: 1 | B25: 4800 | C25: 0 | D25: 4800
A26: 2 | B26: 5200 | C26: 0 | D26: 5200
A27: 3 | B27: 3600 | C27: 0 | D27: 3600
A28: 4 | B28: 1200 | C28: 2400 | D28: 3600
A29: 5 | B29: 2400 | C29: 1200 | D29: 3600
A30: 6 | B30: 6600 | C30: 4800 | D30: 11400
A31: 7 | B31: 10800 | C31: 6000 | D31: 16800
A32: 8 | B32: 11400 | C32: 3600 | D32: 15000
A33: 9 | B33: 6000 | C33: 6000 | D33: 12000
A34: 10 | B34: 1200 | C34: 9600 | D34: 10800
A35: 11 | B35: 0 | C35: 10800 | D35: 10800
A36: 12 | B36: 0 | C36: 12600 | D36: 12600
... A42: 5 | B42: 0 | C42: 0 | D42: 0
A43: 总计 | B43: 53200 | C43: 61800 | D43: 115000
B61: 列标签
B62: 1月 | E62: 2月 | H62: 3月 | K62: 4月 | N62: 5月 | Q62: 6月 | T62: 7月 | W62: 8月 | Z62: 9月 | AC62: 10月 | AF62: 求和项:首次缴费汇总 | AG62: 求和项:总续费金额汇总 | AH62: 平均值项:学员生命周期价值 (LTV)汇总
A63: 行标签 | B63: 求和项:首次缴费 | C63: 求和项:总续费金额 | D63: 平均值项:学员生命周期价值 (LTV) | E63: 求和项:首次缴费 | F63: 求和项:总续费金额 | G63: 平均值项:学员生命周期价值 (LTV) | H63: 求和项:首次缴费 | I63: 求和项:总续费金额 | J63: 平均值项:学员生命周期价值 (LTV) | K63: 求和项:首次缴费 | L63: 求和项:总续费金额 | M63: 平均值项:学员生命周期价值 (LTV) | N63: 求和项:首次缴费 | O63: 求和项:总续费金额 | P63: 平均值项:学员生命周期价值 (LTV) | Q63: 求和项:首次缴费 | R63: 求和项:总续费金额 | S63: 平均值项:学员生命周期价值 (LTV) | T63: 求和项:首次缴费 | U63: 求和项:总续费金额 | V63: 平均值项:学员生命周期价值 (LTV) | W63: 求和项:首次缴费 | X63: 求和项:总续费金额 | Y63: 平均值项:学员生命周期价值 (LTV) | Z63: 求和项:首次缴费 | AA63: 求和项:总续费金额 | AB63: 平均值项:学员生命周期价值 (LTV) | AC63: 求和项:首次缴费 | AD63: 求和项:总续费金额 | AE63: 平均值项:学员生命周期价值 (LTV)
A64: 2025 | B64: 4800 | C64: 10800 | D64: 5200 | E64: 5200 | F64: 10800 | G64: 5333.3333 | H64: 3600 | I64: 10800 | J64: 4800 | K64: 1200 | L64: 3600 | M64: 4800 | N64: 2400 | O64: 1200 | P64: 3600 | Q64: 6600 | R64: 4200 | S64: 3600 | T64: 10800 | U64: 9000 | V64: 3300 | W64: 11400 | X64: 6600 | Y64: 2571.4286 | Z64: 6000 | AA64: 3600 | AB64: 2400 | AC64: 1200 | AD64: 1200 | AE64: 2400 | AF64: 53200 | AG64: 61800 | AH64: 3593.75
A65: c++ | E65: 2000 | F65: 3600 | G65: 5600 | W65: 9000 | X65: 4200 | Y65: 2640 | AF65: 11000 | AG65: 7800 | AH65: 3133.3333
A66: Python | B66: 2400 | C66: 3600 | D66: 6000 | Q66: 1200 | R66: 2400 | S66: 3600 | T66: 1200 | U66: 2400 | V66: 3600 | W66: 1200 | X66: 1200 | Y66: 2400 | Z66: 2400 | AA66: 0 | AB66: 2400 | AF66: 8400 | AG66: 9600 | AH66: 3600
A67: scratch | B67: 2400 | C67: 7200 | D67: 4800 | E67: 3200 | F67: 7200 | G67: 5200 | H67: 3600 | I67: 10800 | J67: 4800 | K67: 1200 | L67: 3600 | M67: 4800 | N67: 2400 | O67: 1200 | P67: 3600 | Q67: 5400 | R67: 1800 | S67: 3600 | T67: 9600 | U67: 6600 | V67: 3240 | W67: 1200 | X67: 1200 | Y67: 2400 | Z67: 3600 | AA67: 3600 | AB67: 2400 | AC67: 1200 | AD67: 1200 | AE67: 2400 | AF67: 33800 | AG67: 44400 | AH67: 3723.8095
A68: 总计 | B68: 4800 | C68: 10800 | D68: 5200 | E68: 5200 | F68: 10800 | G68: 5333.3333 | H68: 3600 | I68: 10800 | J68: 4800 | K68: 1200 | L68: 3600 | M68: 4800 | N68: 2400 | O68: 1200 | P68: 3600 | Q68: 6600 | R68: 4200 | S68: 3600 | T68: 10800 | U68: 9000 | V68: 3300 | W68: 11400 | X68: 6600 | Y68: 2571.4286 | Z68: 6000 | AA68: 3600 | AB68: 2400 | AC68: 1200 | AD68: 1200 | AE68: 2400 | AF68: 53200 | AG68: 61800 | AH68: 3593.75
H73: Scratch 课程是核心营收来源，2025 年累计营收占比超 60%，同比 2024 年有显著增长，是公司的基本盘课程； Python 课程 2025 年平均 LTV 最高，续费率超 100%，学员长期价值最高，是高潜力增长课程，应重点推广； C++ 课程暑期招生表现亮眼，但续费率偏低，需优化课后服务、赛事考级运营提升学员留存。
A97: 行标签 | B97: 计数项:学员 ID | C97: 求和项:首次缴费 | D97: 求和项:总续费金额 | E97: 求和项:合计总收入
A98: 2025 | B98: 32 | C98: 53200 | D98: 61800 | E98: 115000
A99: 低价值 | B99: 10 | C99: 14400 | D99: 9600 | E99: 24000
A100: 高价值 | B100: 3 | C100: 6400 | D100: 10800 | E100: 17200 | G100: 高价值学员仅占总学员数的 20%，但贡献了 60% 以上的总营收，符合二八定律，是核心运营对象，运营资源应向高价值学员倾斜； 2025 年高价值学员占比同比 2024 年提升明显，学员分层运营效果显著； 高价值学员的考级 / 参赛占比超 80%，赛事考级活动是提升学员生命周期价值的核心抓手。
A101: 中价值 | B101: 19 | C101: 32400 | D101: 41400 | E101: 73800
A102: 总计 | B102: 32 | C102: 53200 | D102: 61800 | E102: 115000
A124: 行标签 | B124: 计数项:学员 ID | C124: 平均值项:学员生命周期价值 (LTV) | D124: 平均值项:报名到首续费间隔天数
A125: 否 | B125: 1 | C125: 2400 | D125: 84 | J125: 同时参加考级 + 赛事的学员，平均续费率是无考级无参赛学员的 2 倍，平均 LTV 高 3 倍，说明赛事和考级活动能显著提升学员留存和生命周期价值； 仅考级的学员续费率也显著高于普通学员，说明考级活动是提升学员留存的有效抓手； 有参赛经历的学员，报名到首续费的间隔天数更短，转化效率更高，说明赛事活动能有效提升学员的付费意愿。
A126: 否 | B126: 1 | C126: 2400 | D126: 84
A127: 是 | B127: 31 | C127: 3632.2581 | D127: 121.93548
...

Sheet 经营看板

Sheet 全学员总表
A1: 学员 ID | B1: 姓名 | C1: 课程科目 | D1: 报名日期 | E1: 报名课时 | F1: 首次缴费 | G1: 总续费金额 | H1: 是否续费 | I1: cpa考级等级 | J1: 电子学会考级结果 | K1: CCF-GESP考级结果 | L1: 信息素养大赛 | M1: 人工智能挑战赛 | N1: 学员分类标签 | O1: 合计总收入 | P1: 报名年份 | Q1: 报名月份 | R1: 首次续费时间 | S1: 报名到首续费间隔天数 | T1: 累计续费次数 | U1: 累计续费总金额 | V1: 是否有考级 | W1: 是否有参赛 | X1: 学员生命周期价值 (LTV) | Y1: 学员价值分层 | Z1: 续费率达标判断
A2: 1 | B2: =VLOOKUP($A2,学生基本信息!$A:$F,2,0) -> 陈宇轩 | C2: =VLOOKUP($A2,学生基本信息!$A:$F,3,0) -> scratch | D2: =VLOOKUP($A2,学生基本信息!$A:$F,4,0) -> 45676 | E2: =VLOOKUP($A2,学生基本信息!$A:$F,5,0) -> 12 | F2: =VLOOKUP($A2,学生基本信息!$A:$F,6,0) -> 1200 | G2: =VLOOKUP($A2,续费情况!$A:$W,13,0)+VLOOKUP($A2,续费情况!$A:$W,17,0)+VLOOKUP($A2,续费情况!$A:$W,21,0) -> 3600 | H2: =VLOOKUP($A2,续费情况!$A:$W,11,0) -> TRUE | I2: =IF(VLOOKUP($A2,学生考级成绩!$A:$E,4,0)=0,"",VLOOKUP($A2,学生考级成绩!$A:$E,4,0)) -> 二级 | J2: =IF(VLOOKUP($A2,学生考级成绩!$A:$E,5,0)=0,"",VLOOKUP($A2,学生考级成绩!$A:$E,5,0)) | K2: =IF(VLOOKUP($A2,学生考级成绩!$A:$F,6,0)=0,"",VLOOKUP($A2,学生考级成绩!$A:$F,6,0)) | L2: =IF(VLOOKUP($A2,'2025全国青少年信息素养大赛'!$A:$H,5,0)="已报名","已参赛","未参赛") -> 未参赛 | M2: =IF(VLOOKUP($A2,全国青少年人工智能创新挑战赛!$A:$H,5,0)="已报名","已参赛","未参赛") -> 未参赛 | N2: =IF(AND(OR(I2<>"",J2<>"",K2<>""),OR(L2="已参赛",M2="已参赛")),"重赛考", IF(OR(I2<>"",J2<>"",K2<>""),"潜力", IF(OR(L2="已参赛",M2="已参赛"),"仅比赛","待推荐"))) -> 潜力 | O2: =F2+G2 -> 4800 | P2: =YEAR(D2) -> 2025 | Q2: =MONTH(D2) -> 1 | R2: =VLOOKUP($A2,续费情况!$A:$X,10,0) -> 45760 | S2: =IFERROR(R2-D2,"") -> 84 | T2: =COUNTIFS(续费情况!$A:$A,$A2,续费情况!$K:$K,TRUE)+COUNTIFS(续费情况!$A:$A,$A2,续费情况!$O:$O,TRUE)+COUNTIFS(续费情况!$A:$A,$A2,续费情况!$S:$S,TRUE) -> 3 | U2: =G2 -> 3600 | V2: =IF(OR(I2<>"",J2<>"",K2<>""),"是","否") -> 是 | W2: =IF(OR(L2="已参赛",M2="已参赛"),"是","否") -> 否 | X2: =F2+G2 -> 4800 | Y2: =IF(X2>=5000,"高价值",IF(X2>=3000,"中价值","低价值")) -> 中价值 | Z2: =IF(G2/F2>=1,"续费率达标","未达标") -> 续费率达标
A3: 2 | B3: =VLOOKUP($A3,学生基本信息!$A:$F,2,0) -> 李浩泽 | C3: =VLOOKUP($A3,学生基本信息!$A:$F,3,0) -> Python | D3: =VLOOKUP($A3,学生基本信息!$A:$F,4,0) -> 45682 | E3: =VLOOKUP($A3,学生基本信息!$A:$F,5,0) -> 24 | F3: =VLOOKUP($A3,学生基本信息!$A:$F,6,0) -> 2400 | G3: =VLOOKUP($A3,续费情况!$A:$W,13,0)+VLOOKUP($A3,续费情况!$A:$W,17,0)+VLOOKUP($A3,续费情况!$A:$W,21,0) -> 3600 | H3: =VLOOKUP($A3,续费情况!$A:$W,11,0) -> TRUE | I3: =IF(VLOOKUP($A3,学生考级成绩!$A:$E,4,0)=0,"",VLOOKUP($A3,学生考级成绩!$A:$E,4,0)) | J3: =IF(VLOOKUP($A3,学生考级成绩!$A:$E,5,0)=0,"",VLOOKUP($A3,学生考级成绩!$A:$E,5,0)) -> 四级 | K3: =IF(VLOOKUP($A3,学生考级成绩!$A:$F,6,0)=0,"",VLOOKUP($A3,学生考级成绩!$A:$F,6,0)) | L3: =IF(VLOOKUP($A3,'2025全国青少年信息素养大赛'!$A:$H,5,0)="已报名","已参赛","未参赛") -> 已参赛 | M3: =IF(VLOOKUP($A3,全国青少年人工智能创新挑战赛!$A:$H,5,0)="已报名","已参赛","未参赛") -> 已参赛 | N3: =IF(AND(OR(I3<>"",J3<>"",K3<>""),OR(L3="已参赛",M3="已参赛")),"重赛考", IF(OR(I3<>"",J3<>"",K3<>""),"潜力", IF(OR(L3="已参赛",M3="已参赛"),"仅比赛","待推荐"))) -> 重赛考 | O3: =F3+G3 -> 6000 | P3: =YEAR(D3) -> 2025 | Q3: =MONTH(D3) -> 1 | R3: =VLOOKUP($A3,续费情况!$A:$X,10,0) -> 45850 | S3: =IFERROR(R3-D3,"") -> 168 | T3: =COUNTIFS(续费情况!$A:$A,$A3,续费情况!$K:$K,TRUE)+COUNTIFS(续费情况!$A:$A,$A3,续费情况!$O:$O,TRUE)+COUNTIFS(续费情况!$A:$A,$A3,续费情况!$S:$S,TRUE) -> 3 | U3: =G3 -> 3600 | V3: =IF(OR(I3<>"",J3<>"",K3<>""),"是","否") -> 是 | W3: =IF(OR(L3="已参赛",M3="已参赛"),"是","否") -> 是 | X3: =F3+G3 -> 6000 | Y3: =IF(X3>=5000,"高价值",IF(X3>=3000,"中价值","低价值")) -> 高价值 | Z3: =IF(G3/F3>=1,"续费率达标","未达标") -> 续费率达标
A4: 3 | B4: =VLOOKUP($A4,学生基本信息!$A:$F,2,0) -> 王梓航 | C4: =VLOOKUP($A4,学生基本信息!$A:$F,3,0) -> scratch | D4: =VLOOKUP($A4,学生基本信息!$A:$F,4,0) -> 45682 | E4: =VLOOKUP($A4,学生基本信息!$A:$F,5,0) -> 12 | F4: =VLOOKUP($A4,学生基本信息!$A:$F,6,0) -> 1200 | G4: =VLOOKUP($A4,续费情况!$A:$W,13,0)+VLOOKUP($A4,续费情况!$A:$W,17,0)+VLOOKUP($A4,续费情况!$A:$W,21,0) -> 3600 | H4: =VLOOKUP($A4,续费情况!$A:$W,11,0) -> TRUE | I4: =IF(VLOOKUP($A4,学生考级成绩!$A:$E,4,0)=0,"",VLOOKUP($A4,学生考级成绩!$A:$E,4,0)) -> 二级 | J4: =IF(VLOOKUP($A4,学生考级成绩!$A:$E,5,0)=0,"",VLOOKUP($A4,学生考级成绩!$A:$E,5,0)) | K4: =IF(VLOOKUP($A4,学生考级成绩!$A:$F,6,0)=0,"",VLOOKUP($A4,学生考级成绩!$A:$F,6,0)) | L4: =IF(VLOOKUP($A4,'2025全国青少年信息素养大赛'!$A:$H,5,0)="已报名","已参赛","未参赛") -> 已参赛 | M4: =IF(VLOOKUP($A4,全国青少年人工智能创新挑战赛!$A:$H,5,0)="已报名","已参赛","未参赛") -> 已参赛 | N4: =IF(AND(OR(I4<>"",J4<>"",K4<>""),OR(L4="已参赛",M4="已参赛")),"重赛考", IF(OR(I4<>"",J4<>"",K4<>""),"潜力", IF(OR(L4="已参赛",M4="已参赛"),"仅比赛","待推荐"))) -> 重赛考 | O4: =F4+G4 -> 4800 | P4: =YEAR(D4) -> 2025 | Q4: =MONTH(D4) -> 1 | R4: =VLOOKUP($A4,续费情况!$A:$X,10,0) -> 45766 | S4: =IFERROR(R4-D4,"") -> 84 | T4: =COUNTIFS(续费情况!$A:$A,$A4,续费情况!$K:$K,TRUE)+COUNTIFS(续费情况!$A:$A,$A4,续费情况!$O:$O,TRUE)+COUNTIFS(续费情况!$A:$A,$A4,续费情况!$S:$S,TRUE) -> 3 | U4: =G4 -> 3600 | V4: =IF(OR(I4<>"",J4<>"",K4<>""),"是","否") -> 是 | W4: =IF(OR(L4="已参赛",M4="已参赛"),"是","否") -> 是 | X4: =F4+G4 -> 4800 | Y4: =IF(X4>=5000,"高价值",IF(X4>=3000,"中价值","低价值")) -> 中价值 | Z4: =IF(G4/F4>=1,"续费率达标","未达标") -> 续费率达标
A5: 4 | B5: =VLOOKUP($A5,学生基本信息!$A:$F,2,0) -> 张锦程 | C5: =VLOOKUP($A5,学生基本信息!$A:$F,3,0) -> scratch | D5: =VLOOKUP($A5,学生基本信息!$A:$F,4,0) -> 45691 | E5: =VLOOKUP($A5,学生基本信息!$A:$F,5,0) -> 24 | F5: =VLOOKUP($A5,学生基本信息!$A:$F,6,0) -> 2000 | G5: =VLOOKUP($A5,续费情况!$A:$W,13,0)+VLOOKUP($A5,续费情况!$A:$W,17,0)+VLOOKUP($A5,续费情况!$A:$W,21,0) -> 3600 | H5: =VLOOKUP($A5,续费情况!$A:$W,11,0) -> TRUE | I5: =IF(VLOOKUP($A5,学生考级成绩!$A:$E,4,0)=0,"",VLOOKUP($A5,学生考级成绩!$A:$E,4,0)) -> 二级 | J5: =IF(VLOOKUP($A5,学生考级成绩!$A:$E,5,0)=0,"",VLOOKUP($A5,学生考级成绩!$A:$E,5,0)) | K5: =IF(VLOOKUP($A5,学生考级成绩!$A:$F,6,0)=0,"",VLOOKUP($A5,学生考级成绩!$A:$F,6,0)) | L5: =IF(VLOOKUP($A5,'2025全国青少年信息素养大赛'!$A:$H,5,0)="已报名","已参赛","未参赛") -> 已参赛 | M5: =IF(VLOOKUP($A5,全国青少年人工智能创新挑战赛!$A:$H,5,0)="已报名","已参赛","未参赛") -> 已参赛 | N5: =IF(AND(OR(I5<>"",J5<>"",K5<>""),OR(L5="已参赛",M5="已参赛")),"重赛考", IF(OR(I5<>"",J5<>"",K5<>""),"潜力", IF(OR(L5="已参赛",M5="已参赛"),"仅比赛","待推荐"))) -> 重赛考 | O5: =F5+G5 -> 5600 | P5: =YEAR(D5) -> 2025 | Q5: =MONTH(D5) -> 2 | R5: =VLOOKUP($A5,续费情况!$A:$X,10,0) -> 45859 | S5: =IFERROR(R5-D5,"") -> 168 | T5: =COUNTIFS(续费情况!$A:$A,$A5,续费情况!$K:$K,TRUE)+COUNTIFS(续费情况!$A:$A,$A5,续费情况!$O:$O,TRUE)+COUNTIFS(续费情况!$A:$A,$A5,续费情况!$S:$S,TRUE) -> 3 | U5: =G5 -> 3600 | V5: =IF(OR(I5<>"",J5<>"",K5<>""),"是","否") -> 是 | W5: =IF(OR(L5="已参赛",M5="已参赛"),"是","否") -> 是 | X5: =F5+G5 -> 5600 | Y5: =IF(X5>=5000,"高价值",IF(X5>=3000,"中价值","低价值")) -> 高价值 | Z5: =IF(G5/F5>=1,"续费率达标","未达标") -> 续费率达标
A6: 5 | B6: =VLOOKUP($A6,学生基本信息!$A:$F,2,0) -> 张俊豪 | C6: =VLOOKUP($A6,学生基本信息!$A:$F,3,0) -> c++ | D6: =VLOOKUP($A6,学生基本信息!$A:$F,4,0) -> 45691 | E6: =VLOOKUP($A6,学生基本信息!$A:$F,5,0) -> 24 | F6: =VLOOKUP($A6,学生基本信息!$A:$F,6,0) -> 2000 | G6: =VLOOKUP($A6,续费情况!$A:$W,13,0)+VLOOKUP($A6,续费情况!$A:$W,17,0)+VLOOKUP($A6,续费情况!$A:$W,21,0) -> 3600 | H6: =VLOOKUP($A6,续费情况!$A:$W,11,0) -> TRUE | I6: =IF(VLOOKUP($A6,学生考级成绩!$A:$E,4,0)=0,"",VLOOKUP($A6,学生考级成绩!$A:$E,4,0)) | J6: =IF(VLOOKUP($A6,学生考级成绩!$A:$E,5,0)=0,"",VLOOKUP($A6,学生考级成绩!$A:$E,5,0)) | K6: =IF(VLOOKUP($A6,学生考级成绩!$A:$F,6,0)=0,"",VLOOKUP($A6,学生考级成绩!$A:$F,6,0)) -> 三级 | L6: =IF(VLOOKUP($A6,'2025全国青少年信息素养大赛'!$A:$H,5,0)="已报名","已参赛","未参赛") -> 已参赛 | M6: =IF(VLOOKUP($A6,全国青少年人工智能创新挑战赛!$A:$H,5,0)="已报名","已参赛","未参赛") -> 已参赛 | N6: =IF(AND(OR(I6<>"",J6<>"",K6<>""),OR(L6="已参赛",M6="已参赛")),"重赛考", IF(OR(I6<>"",J6<>"",K6<>""),"潜力", IF(OR(L6="已参赛",M6="已参赛"),"仅比赛","待推荐"))) -> 重赛考 | O6: =F6+G6 -> 5600 | P6: =YEAR(D6) -> 2025 | Q6: =MONTH(D6) -> 2 | R6: =VLOOKUP($A6,续费情况!$A:$X,10,0) -> 45859 | S6: =IFERROR(R6-D6,"") -> 168 | T6: =COUNTIFS(续费情况!$A:$A,$A6,续费情况!$K:$K,TRUE)+COUNTIFS(续费情况!$A:$A,$A6,续费情况!$O:$O,TRUE)+COUNTIFS(续费情况!$A:$A,$A6,续费情况!$S:$S,TRUE) -> 3 | U6: =G6 -> 3600 | V6: =IF(OR(I6<>"",J6<>"",K6<>""),"是","否") -> 是 | W6: =IF(OR(L6="已参赛",M6="已参赛"),"是","否") -> 是 | X6: =F6+G6 -> 5600 | Y6: =IF(X6>=5000,"高价值",IF(X6>=3000,"中价值","低价值")) -> 高价值 | Z6: =IF(G6/F6>=1,"续费率达标","未达标") -> 续费率达标
A7: 6 | B7: =VLOOKUP($A7,学生基本信息!$A:$F,2,0) -> 李若溪 | C7: =VLOOKUP($A7,学生基本信息!$A:$F,3,0) -> scratch | D7: =VLOOKUP($A7,学生基本信息!$A:$F,4,0) -> 45703 | E7: =VLOOKUP($A7,学生基本信息!$A:$F,5,0) -> 12 | F7: =VLOOKUP($A7,学生基本信息!$A:$F,6,0) -> 1200 | G7: =VLOOKUP($A7,续费情况!$A:$W,13,0)+VLOOKUP($A7,续费情况!$A:$W,17,0)+VLOOKUP($A7,续费情况!$A:$W,21,0) -> 3600 | H7: =VLOOKUP($A7,续费情况!$A:$W,11,0) -> TRUE | I7: =IF(VLOOKUP($A7,学生考级成绩!$A:$E,4,0)=0,"",VLOOKUP($A7,学生考级成绩!$A:$E,4,0)) -> 二级 | J7: =IF(VLOOKUP($A7,学生考级成绩!$A:$E,5,0)=0,"",VLOOKUP($A7,学生考级成绩!$A:$E,5,0)) | K7: =IF(VLOOKUP($A7,学生考级成绩!$A:$F,6,0)=0,"",VLOOKUP($A7,学生考级成绩!$A:$F,6,0)) | L7: =IF(VLOOKUP($A7,'2025全国青少年信息素养大赛'!$A:$H,5,0)="已报名","已参赛","未参赛") -> 未参赛 | M7: =IF(VLOOKUP($A7,全国青少年人工智能创新挑战赛!$A:$H,5,0)="已报名","已参赛","未参赛") -> 未参赛 | N7: =IF(AND(OR(I7<>"",J7<>"",K7<>""),OR(L7="已参赛",M7="已参赛")),"重赛考", IF(OR(I7<>"",J7<>"",K7<>""),"潜力", IF(OR(L7="已参赛",M7="已参赛"),"仅比赛","待推荐"))) -> 潜力 | O7: =F7+G7 -> 4800 | P7: =YEAR(D7) -> 2025 | Q7: =MONTH(D7) -> 2 | R7: =VLOOKUP($A7,续费情况!$A:$X,10,0) -> 45787 | S7: =IFERROR(R7-D7,"") -> 84 | T7: =COUNTIFS(续费情况!$A:$A,$A7,续费情况!$K:$K,TRUE)+COUNTIFS(续费情况!$A:$A,$A7,续费情况!$O:$O,TRUE)+COUNTIFS(续费情况!$A:$A,$A7,续费情况!$S:$S,TRUE) -> 3 | U7: =G7 -> 3600 | V7: =IF(OR(I7<>"",J7<>"",K7<>""),"是","否") -> 是 | W7: =IF(OR(L7="已参赛",M7="已参赛"),"是","否") -> 否 | X7: =F7+G7 -> 4800 | Y7: =IF(X7>=5000,"高价值",IF(X7>=3000,"中价值","低价值")) -> 中价值 | Z7: =IF(G7/F7>=1,"续费率达标","未达标") -> 续费率达标
A8: 7 | B8: =VLOOKUP($A8,学生基本信息!$A:$F,2,0) -> 周思远 | C8: =VLOOKUP($A8,学生基本信息!$A:$F,3,0) -> scratch | D8: =VLOOKUP($A8,学生基本信息!$A:$F,4,0) -> 45725 | E8: =VLOOKUP($A8,学生基本信息!$A:$F,5,0) -> 12 | F8: =VLOOKUP($A8,学生基本信息!$A:$F,6,0) -> 1200 | G8: =VLOOKUP($A8,续费情况!$A:$W,13,0)+VLOOKUP($A8,续费情况!$A:$W,17,0)+VLOOKUP($A8,续费情况!$A:$W,21,0) -> 3600 | H8: =VLOOKUP($A8,续费情况!$A:$W,11,0) -> TRUE | I8: =IF(VLOOKUP($A8,学生考级成绩!$A:$E,4,0)=0,"",VLOOKUP($A8,学生考级成绩!$A:$E,4,0)) -> 二级 | J8: =IF(VLOOKUP($A8,学生考级成绩!$A:$E,5,0)=0,"",VLOOKUP($A8,学生考级成绩!$A:$E,5,0)) | K8: =IF(VLOOKUP($A8,学生考级成绩!$A:$F,6,0)=0,"",VLOOKUP($A8,学生考级成绩!$A:$F,6,0)) | L8: =IF(VLOOKUP($A8,'2025全国青少年信息素养大赛'!$A:$H,5,0)="已报名","已参赛","未参赛") -> 未参赛 | M8: =IF(VLOOKUP($A8,全国青少年人工智能创新挑战赛!$A:$H,5,0)="已报名","已参赛","未参赛") -> 未参赛 | N8: =IF(AND(OR(I8<>"",J8<>"",K8<>""),OR(L8="已参赛",M8="已参赛")),"重赛考", IF(OR(I8<>"",J8<>"",K8<>""),"潜力", IF(OR(L8="已参赛",M8="已参赛"),"仅比赛","待推荐"))) -> 潜力 | O8: =F8+G8 -> 4800 | P8: =YEAR(D8) -> 2025 | Q8: =MONTH(D8) -> 3 | R8: =VLOOKUP($A8,续费情况!$A:$X,10,0) -> 45809 | S8: =IFERROR(R8-D8,"") -> 84 | T8: =COUNTIFS(续费情况!$A:$A,$A8,续费情况!$K:$K,TRUE)+COUNTIFS(续费情况!$A:$A,$A8,续费情况!$O:$O,TRUE)+COUNTIFS(续费情况!$A:$A,$A8,续费情况!$S:$S,TRUE) -> 3 | U8: =G8 -> 3600 | V8: =IF(OR(I8<>"",J8<>"",K8<>""),"是","否") -> 是 | W8: =IF(OR(L8="已参赛",M8="已参赛"),"是","否") -> 否 | X8: =F8+G8 -> 4800 | Y8: =IF(X8>=5000,"高价值",IF(X8>=3000,"中价值","低价值")) -> 中价值 | Z8: =IF(G8/F8>=1,"续费率达标","未达标") -> 续费率达标
A9: 8 | B9: =VLOOKUP($A9,学生基本信息!$A:$F,2,0) -> 吴嘉硕 | C9: =VLOOKUP($A9,学生基本信息!$A:$F,3,0) -> scratch | D9: =VLOOKUP($A9,学生基本信息!$A:$F,4,0) -> 45730 | E9: =VLOOKUP($A9,学生基本信息!$A:$F,5,0) -> 12 | F9: =VLOOKUP($A9,学生基本信息!$A:$F,6,0) -> 1200 | G9: =VLOOKUP($A9,续费情况!$A:$W,13,0)+VLOOKUP($A9,续费情况!$A:$W,17,0)+VLOOKUP($A9,续费情况!$A:$W,21,0) -> 3600 | H9: =VLOOKUP($A9,续费情况!$A:$W,11,0) -> TRUE | I9: =IF(VLOOKUP($A9,学生考级成绩!$A:$E,4,0)=0,"",VLOOKUP($A9,学生考级成绩!$A:$E,4,0)) -> 二级 | J9: =IF(VLOOKUP($A9,学生考级成绩!$A:$E,5,0)=0,"",VLOOKUP($A9,学生考级成绩!$A:$E,5,0)) | K9: =IF(VLOOKUP($A9,学生考级成绩!$A:$F,6,0)=0,"",VLOOKUP($A9,学生考级成绩!$A:$F,6,0)) | L9: =IF(VLOOKUP($A9,'2025全国青少年信息素养大赛'!$A:$H,5,0)="已报名","已参赛","未参赛") -> 已参赛 | M9: =IF(VLOOKUP($A9,全国青少年人工智能创新挑战赛!$A:$H,5,0)="已报名","已参赛","未参赛") -> 未参赛 | N9: =IF(AND(OR(I9<>"",J9<>"",K9<>""),OR(L9="已参赛",M9="已参赛")),"重赛考", IF(OR(I9<>"",J9<>"",K9<>""),"潜力", IF(OR(L9="已参赛",M9="已参赛"),"仅比赛","待推荐"))) -> 重赛考 | O9: =F9+G9 -> 4800 | P9: =YEAR(D9) -> 2025 | Q9: =MONTH(D9) -> 3 | R9: =VLOOKUP($A9,续费情况!$A:$X,10,0) -> 45814 | S9: =IFERROR(R9-D9,"") -> 84 | T9: =COUNTIFS(续费情况!$A:$A,$A9,续费情况!$K:$K,TRUE)+COUNTIFS(续费情况!$A:$A,$A9,续费情况!$O:$O,TRUE)+COUNTIFS(续费情况!$A:$A,$A9,续费情况!$S:$S,TRUE) -> 3 | U9: =G9 -> 3600 | V9: =IF(OR(I9<>"",J9<>"",K9<>""),"是","否") -> 是 | W9: =IF(OR(L9="已参赛",M9="已参赛"),"是","否") -> 是 | X9: =F9+G9 -> 4800 | Y9: =IF(X9>=5000,"高价值",IF(X9>=3000,"中价值","低价值")) -> 中价值 | Z9: =IF(G9/F9>=1,"续费率达标","未达标") -> 续费率达标
A10: 9 | B10: =VLOOKUP($A10,学生基本信息!$A:$F,2,0) -> 郑博文 | C10: =VLOOKUP($A10,学生基本信息!$A:$F,3,0) -> scratch | D10: =VLOOKUP($A10,学生基本信息!$A:$F,4,0) -> 45739 | E10: =VLOOKUP($A10,学生基本信息!$A:$F,5,0) -> 12 | F10: =VLOOKUP($A10,学生基本信息!$A:$F,6,0) -> 1200 | G10: =VLOOKUP($A10,续费情况!$A:$W,13,0)+VLOOKUP($A10,续费情况!$A:$W,17,0)+VLOOKUP($A10,续费情况!$A:$W,21,0) -> 3600 | H10: =VLOOKUP($A10,续费情况!$A:$W,11,0) -> TRUE | I10: =IF(VLOOKUP($A10,学生考级成绩!$A:$E,4,0)=0,"",VLOOKUP($A10,学生考级成绩!$A:$E,4,0)) -> 一级 | J10: =IF(VLOOKUP($A10,学生考级成绩!$A:$E,5,0)=0,"",VLOOKUP($A10,学生考级成绩!$A:$E,5,0)) | K10: =IF(VLOOKUP($A10,学生考级成绩!$A:$F,6,0)=0,"",VLOOKUP($A10,学生考级成绩!$A:$F,6,0)) | L10: =IF(VLOOKUP($A10,'2025全国青少年信息素养大赛'!$A:$H,5,0)="已报名","已参赛","未参赛") -> 已参赛 | M10: =IF(VLOOKUP($A10,全国青少年人工智能创新挑战赛!$A:$H,5,0)="已报名","已参赛","未参赛") -> 未参赛 | N10: =IF(AND(OR(I10<>"",J10<>"",K10<>""),OR(L10="已参赛",M10="已参赛")),"重赛考", IF(OR(I10<>"",J10<>"",K10<>""),"潜力", IF(OR(L10="已参赛",M10="已参赛"),"仅比赛","待推荐"))) -> 重赛考 | O10: =F10+G10 -> 4800 | P10: =YEAR(D10) -> 2025 | Q10: =MONTH(D10) -> 3 | R10: =VLOOKUP($A10,续费情况!$A:$X,10,0) -> 45823 | S10: =IFERROR(R10-D10,"") -> 84 | T10: =COUNTIFS(续费情况!$A:$A,$A10,续费情况!$K:$K,TRUE)+COUNTIFS(续费情况!$A:$A,$A10,续费情况!$O:$O,TRUE)+COUNTIFS(续费情况!$A:$A,$A10,续费情况!$S:$S,TRUE) -> 3 | U10: =G10 -> 3600 | V10: =IF(OR(I10<>"",J10<>"",K10<>""),"是","否") -> 是 | W10: =IF(OR(L10="已参赛",M10="已参赛"),"是","否") -> 是 | X10: =F10+G10 -> 4800 | Y10: =IF(X10>=5000,"高价值",IF(X10>=3000,"中价值","低价值")) -> 中价值 | Z10: =IF(G10/F10>=1,"续费率达标","未达标") -> 续费率达标
A11: 10 | B11: =VLOOKUP($A11,学生基本信息!$A:$F,2,0) -> 骆思玥 | C11: =VLOOKUP($A11,学生基本信息!$A:$F,3,0) -> scratch | D11: =VLOOKUP($A11,学生基本信息!$A:$F,4,0) -> 45753 | E11: =VLOOKUP($A11,学生基本信息!$A:$F,5,0) -> 12 | F11: =VLOOKUP($A11,学生基本信息!$A:$F,6,0) -> 1200 | G11: =VLOOKUP($A11,续费情况!$A:$W,13,0)+VLOOKUP($A11,续费情况!$A:$W,17,0)+VLOOKUP($A11,续费情况!$A:$W,21,0) -> 3600 | H11: =VLOOKUP($A11,续费情况!$A:$W,11,0) -> TRUE | I11: =IF(VLOOKUP($A11,学生考级成绩!$A:$E,4,0)=0,"",VLOOKUP($A11,学生考级成绩!$A:$E,4,0)) -> 二级 | J11: =IF(VLOOKUP($A11,学生考级成绩!$A:$E,5,0)=0,"",VLOOKUP($A11,学生考级成绩!$A:$E,5,0)) | K11: =IF(VLOOKUP($A11,学生考级成绩!$A:$F,6,0)=0,"",VLOOKUP($A11,学生考级成绩!$A:$F,6,0)) | L11: =IF(VLOOKUP($A11,'2025全国青少年信息素养大赛'!$A:$H,5,0)="已报名","已参赛","未参赛") -> 未参赛 | M11: =IF(VLOOKUP($A11,全国青少年人工智能创新挑战赛!$A:$H,5,0)="已报名","已参赛","未参赛") -> 未参赛 | N11: =IF(AND(OR(I11<>"",J11<>"",K11<>""),OR(L11="已参赛",M11="已参赛")),"重赛考", IF(OR(I11<>"",J11<>"",K11<>""),"潜力", IF(OR(L11="已参赛",M11="已参赛"),"仅比赛","待推荐"))) -> 潜力 | O11: =F11+G11 -> 4800 | P11: =YEAR(D11) -> 2025 | Q11: =MONTH(D11) -> 4 | R11: =VLOOKUP($A11,续费情况!$A:$X,10,0) -> 45837 | S11: =IFERROR(R11-D11,"") -> 84 | T11: =COUNTIFS(续费情况!$A:$A,$A11,续费情况!$K:$K,TRUE)+COUNTIFS(续费情况!$A:$A,$A11,续费情况!$O:$O,TRUE)+COUNTIFS(续费情况!$A:$A,$A11,续费情况!$S:$S,TRUE) -> 3 | U11: =G11 -> 3600 | V11: =IF(OR(I11<>"",J11<>"",K11<>""),"是","否") -> 是 | W11: =IF(OR(L11="已参赛",M11="已参赛"),"是","否") -> 否 | X11: =F11+G11 -> 4800 | Y11: =IF(X11>=5000,"高价值",IF(X11>=3000,"中价值","低价值")) -> 中价值 | Z11: =IF(G11/F11>=1,"续费率达标","未达标") -> 续费率达标
A12: 11 | B12: =VLOOKUP($A12,学生基本信息!$A:$F,2,0) -> 黄奕凡 | C12: =VLOOKUP($A12,学生基本信息!$A:$F,3,0) -> scratch | D12: =VLOOKUP($A12,学生基本信息!$A:$F,4,0) -> 45801 | E12: =VLOOKUP($A12,学生基本信息!$A:$F,5,0) -> 24 | F12: =VLOOKUP($A12,学生基本信息!$A:$F,6,0) -> 2400 | G12: =VLOOKUP($A12,续费情况!$A:$W,13,0)+VLOOKUP($A12,续费情况!$A:$W,17,0)+VLOOKUP($A12,续费情况!$A:$W,21,0) -> 1200 | H12: =VLOOKUP($A12,续费情况!$A:$W,11,0) -> TRUE | I12: =IF(VLOOKUP($A12,学生考级成绩!$A:$E,4,0)=0,"",VLOOKUP($A12,学生考级成绩!$A:$E,4,0)) -> 一级 | J12: =IF(VLOOKUP($A12,学生考级成绩!$A:$E,5,0)=0,"",VLOOKUP($A12,学生考级成绩!$A:$E,5,0)) | K12: =IF(VLOOKUP($A12,学生考级成绩!$A:$F,6,0)=0,"",VLOOKUP($A12,学生考级成绩!$A:$F,6,0)) | L12: =IF(VLOOKUP($A12,'2025全国青少年信息素养大赛'!$A:$H,5,0)="已报名","已参赛","未参赛") -> 未参赛 | M12: =IF(VLOOKUP($A12,全国青少年人工智能创新挑战赛!$A:$H,5,0)="已报名","已参赛","未参赛") -> 未参赛 | N12: =IF(AND(OR(I12<>"",J12<>"",K12<>""),OR(L12="已参赛",M12="已参赛")),"重赛考", IF(OR(I12<>"",J12<>"",K12<>""),"潜力", IF(OR(L12="已参赛",M12="已参赛"),"仅比赛","待推荐"))) -> 潜力 | O12: =F12+G12 -> 3600 | P12: =YEAR(D12) -> 2025 | Q12: =MONTH(D12) -> 5 | R12: =VLOOKUP($A12,续费情况!$A:$X,10,0) -> 45969 | S12: =IFERROR(R12-D12,"") -> 168 | T12: =COUNTIFS(续费情况!$A:$A,$A12,续费情况!$K:$K,TRUE)+COUNTIFS(续费情况!$A:$A,$A12,续费情况!$O:$O,TRUE)+COUNTIFS(续费情况!$A:$A,$A12,续费情况!$S:$S,TRUE) -> 1 | U12: =G12 -> 1200 | V12: =IF(OR(I12<>"",J12<>"",K12<>""),"是","否") -> 是 | W12: =IF(OR(L12="已参赛",M12="已参赛"),"是","否") -> 否 | X12: =F12+G12 -> 3600 | Y12: =IF(X12>=5000,"高价值",IF(X12>=3000,"中价值","低价值")) -> 中价值 | Z12: =IF(G12/F12>=1,"续费率达标","未达标") -> 未达标
A13: 12 | B13: =VLOOKUP($A13,学生基本信息!$A:$F,2,0) -> 王语桐 | C13: =VLOOKUP($A13,学生基本信息!$A:$F,3,0) -> scratch | D13: =VLOOKUP($A13,学生基本信息!$A:$F,4,0) -> 45816 | E13: =VLOOKUP($A13,学生基本信息!$A:$F,5,0) -> 36 | F13: =VLOOKUP($A13,学生基本信息!$A:$F,6,0) -> 3000 | G13: =VLOOKUP($A13,续费情况!$A:$W,13,0)+VLOOKUP($A13,续费情况!$A:$W,17,0)+VLOOKUP($A13,续费情况!$A:$W,21,0) -> 600 | H13: =VLOOKUP($A13,续费情况!$A:$W,11,0) -> TRUE | I13: =IF(VLOOKUP($A13,学生考级成绩!$A:$E,4,0)=0,"",VLOOKUP($A13,学生考级成绩!$A:$E,4,0)) -> 三级 | J13: =IF(VLOOKUP($A13,学生考级成绩!$A:$E,5,0)=0,"",VLOOKUP($A13,学生考级成绩!$A:$E,5,0)) | K13: =IF(VLOOKUP($A13,学生考级成绩!$A:$F,6,0)=0,"",VLOOKUP($A13,学生考级成绩!$A:$F,6,0)) | L13: =IF(VLOOKUP($A13,'2025全国青少年信息素养大赛'!$A:$H,5,0)="已报名","已参赛","未参赛") -> 未参赛 | M13: =IF(VLOOKUP($A13,全国青少年人工智能创新挑战赛!$A:$H,5,0)="已报名","已参赛","未参赛") -> 未参赛 | N13: =IF(AND(OR(I13<>"",J13<>"",K13<>""),OR(L13="已参赛",M13="已参赛")),"重赛考", IF(OR(I13<>"",J13<>"",K13<>""),"潜力", IF(OR(L13="已参赛",M13="已参赛"),"仅比赛","待推荐"))) -> 潜力 | O13: =F13+G13 -> 3600 | P13: =YEAR(D13) -> 2025 | Q13: =MONTH(D13) -> 6 | R13: =VLOOKUP($A13,续费情况!$A:$X,10,0) -> 46068 | S13: =IFERROR(R13-D13,"") -> 252 | T13: =COUNTIFS(续费情况!$A:$A,$A13,续费情况!$K:$K,TRUE)+COUNTIFS(续费情况!$A:$A,$A13,续费情况!$O:$O,TRUE)+COUNTIFS(续费情况!$A:$A,$A13,续费情况!$S:$S,TRUE) -> 1 | U13: =G13 -> 600 | V13: =IF(OR(I13<>"",J13<>"",K13<>""),"是","否") -> 是 | W13: =IF(OR(L13="已参赛",M13="已参赛"),"是","否") -> 否 | X13: =F13+G13 -> 3600 | Y13: =IF(X13>=5000,"高价值",IF(X13>=3000,"中价值","低价值")) -> 中价值 | Z13: =IF(G13/F13>=1,"续费率达标","未达标") -> 未达标
... A33: 32 | B33: =VLOOKUP($A33,学生基本信息!$A:$F,2,0) -> 邓崇安 | C33: =VLOOKUP($A33,学生基本信息!$A:$F,3,0) -> scratch | D33: =VLOOKUP($A33,学生基本信息!$A:$F,4,0) -> 45932 | E33: =VLOOKUP($A33,学生基本信息!$A:$F,5,0) -> 12 | F33: =VLOOKUP($A33,学生基本信息!$A:$F,6,0) -> 1200 | G33: =VLOOKUP($A33,续费情况!$A:$W,13,0)+VLOOKUP($A33,续费情况!$A:$W,17,0)+VLOOKUP($A33,续费情况!$A:$W,21,0) -> 1200 | H33: =VLOOKUP($A33,续费情况!$A:$W,11,0) -> TRUE | I33: =IF(VLOOKUP($A33,学生考级成绩!$A:$E,4,0)=0,"",VLOOKUP($A33,学生考级成绩!$A:$E,4,0)) | J33: =IF(VLOOKUP($A33,学生考级成绩!$A:$E,5,0)=0,"",VLOOKUP($A33,学生考级成绩!$A:$E,5,0)) | K33: =IF(VLOOKUP($A33,学生考级成绩!$A:$F,6,0)=0,"",VLOOKUP($A33,学生考级成绩!$A:$F,6,0)) | L33: =IF(VLOOKUP($A33,'2025全国青少年信息素养大赛'!$A:$H,5,0)="已报名","已参赛","未参赛") -> 未参赛 | M33: =IF(VLOOKUP($A33,全国青少年人工智能创新挑战赛!$A:$H,5,0)="已报名","已参赛","未参赛") -> 未参赛 | N33: =IF(AND(OR(I33<>"",J33<>"",K33<>""),OR(L33="已参赛",M33="已参赛")),"重赛考", IF(OR(I33<>"",J33<>"",K33<>""),"潜力", IF(OR(L33="已参赛",M33="已参赛"),"仅比赛","待推荐"))) -> 待推荐 | O33: =F33+G33 -> 2400 | P33: =YEAR(D33) -> 2025 | Q33: =MONTH(D33) -> 10 | R33: =VLOOKUP($A33,续费情况!$A:$X,10,0) -> 46016 | S33: =IFERROR(R33-D33,"") -> 84 | T33: =COUNTIFS(续费情况!$A:$A,$A33,续费情况!$K:$K,TRUE)+COUNTIFS(续费情况!$A:$A,$A33,续费情况!$O:$O,TRUE)+COUNTIFS(续费情况!$A:$A,$A33,续费情况!$S:$S,TRUE) -> 1 | U33: =G33 -> 1200 | V33: =IF(OR(I33<>"",J33<>"",K33<>""),"是","否") -> 否 | W33: =IF(OR(L33="已参赛",M33="已参赛"),"是","否") -> 否 | X33: =F33+G33 -> 2400 | Y33: =IF(X33>=5000,"高价值",IF(X33>=3000,"中价值","低价值")) -> 低价值 | Z33: =IF(G33/F33>=1,"续费率达标","未达标") -> 续费率达标

Sheet 年度月度经营汇总表
A1: 年份 | B1: 月份 | C1: 年月文本 | D1: 当月新签营收 | E1: 当月实收续费 | F1: 月度总营收 | G1: 同比增长率 | H1: 环比增长率 | P1: 针对多列不规则续费宽表，我采用「嵌套 SUMIFS+SUM」的结构，结合 DATE 和 EOMONTH 函数，实现了多列数据的按年 / 月自动化聚合，解决了透视表无法直接汇总的痛点。整个指标体系完全自动化，下拉即可适配所有年份和月份，新增续费列只需复制一行 SUMIFS，维护成本极低。
A2: 2025 | B2: 1 | C2: =A2&"年"&B2&"月" -> 2025年1月 | D2: =SUMIFS(全学员总表!$F:$F, 全学员总表!$P:$P,$A2, 全学员总表!$Q:$Q,$B2) -> 4800 | E2: =SUM( SUMIFS(续费情况!$M:$M, 续费情况!$J:$J,">="&DATE($A2,$B2,1), 续费情况!$J:$J,"<="&EOMONTH(DATE($A2,$B2,1),0)), SUMIFS(续费情况!$Q:$Q, 续费情况!$N:$N,">="&DATE($A2,$B2,1), 续费情况!$N:$N,"<="&EOMONTH(DATE($A2,$B2,1),0)), SUMIFS(续费情况!$U:$U, 续费情况!$R:$R,">="&DATE($A2,$B2,1), 续费情况!$R:$R,"<="&EOMONTH(DATE($A2,$B2,1),0)) ) -> 0 | F2: =D2+E2 -> 4800 | G2: {=IFERROR((F2-INDEX($F:$F,MATCH($A2-1&$B2,$A:$A&$B:$B,0)))/INDEX($F:$F,MATCH($A2-1&$B2,$A:$A&$B:$B,0)),"")}
A3: 2025 | B3: 2 | C3: =A3&"年"&B3&"月" -> 2025年2月 | D3: =SUMIFS(全学员总表!$F:$F, 全学员总表!$P:$P,$A3, 全学员总表!$Q:$Q,$B3) -> 5200 | E3: =SUM( SUMIFS(续费情况!$M:$M, 续费情况!$J:$J,">="&DATE($A3,$B3,1), 续费情况!$J:$J,"<="&EOMONTH(DATE($A3,$B3,1),0)), SUMIFS(续费情况!$Q:$Q, 续费情况!$N:$N,">="&DATE($A3,$B3,1), 续费情况!$N:$N,"<="&EOMONTH(DATE($A3,$B3,1),0)), SUMIFS(续费情况!$U:$U, 续费情况!$R:$R,">="&DATE($A3,$B3,1), 续费情况!$R:$R,"<="&EOMONTH(DATE($A3,$B3,1),0)) ) -> 0 | F3: =D3+E3 -> 5200 | G3: {=IFERROR((F3-INDEX($F:$F,MATCH($A3-1&$B3,$A:$A&$B:$B,0)))/INDEX($F:$F,MATCH($A3-1&$B3,$A:$A&$B:$B,0)),"")} | H3: =IF(A4=A3,(F4-F3)/F3,"") -> -0.30769231
A4: 2025 | B4: 3 | C4: =A4&"年"&B4&"月" -> 2025年3月 | D4: =SUMIFS(全学员总表!$F:$F, 全学员总表!$P:$P,$A4, 全学员总表!$Q:$Q,$B4) -> 3600 | E4: =SUM( SUMIFS(续费情况!$M:$M, 续费情况!$J:$J,">="&DATE($A4,$B4,1), 续费情况!$J:$J,"<="&EOMONTH(DATE($A4,$B4,1),0)), SUMIFS(续费情况!$Q:$Q, 续费情况!$N:$N,">="&DATE($A4,$B4,1), 续费情况!$N:$N,"<="&EOMONTH(DATE($A4,$B4,1),0)), SUMIFS(续费情况!$U:$U, 续费情况!$R:$R,">="&DATE($A4,$B4,1), 续费情况!$R:$R,"<="&EOMONTH(DATE($A4,$B4,1),0)) ) -> 0 | F4: =D4+E4 -> 3600 | G4: {=IFERROR((F4-INDEX($F:$F,MATCH($A4-1&$B4,$A:$A&$B:$B,0)))/INDEX($F:$F,MATCH($A4-1&$B4,$A:$A&$B:$B,0)),"")} | H4: =IF(A5=A4,(F5-F4)/F4,"") -> 0
A5: 2025 | B5: 4 | C5: =A5&"年"&B5&"月" -> 2025年4月 | D5: =SUMIFS(全学员总表!$F:$F, 全学员总表!$P:$P,$A5, 全学员总表!$Q:$Q,$B5) -> 1200 | E5: =SUM( SUMIFS(续费情况!$M:$M, 续费情况!$J:$J,">="&DATE($A5,$B5,1), 续费情况!$J:$J,"<="&EOMONTH(DATE($A5,$B5,1),0)), SUMIFS(续费情况!$Q:$Q, 续费情况!$N:$N,">="&DATE($A5,$B5,1), 续费情况!$N:$N,"<="&EOMONTH(DATE($A5,$B5,1),0)), SUMIFS(续费情况!$U:$U, 续费情况!$R:$R,">="&DATE($A5,$B5,1), 续费情况!$R:$R,"<="&EOMONTH(DATE($A5,$B5,1),0)) ) -> 2400 | F5: =D5+E5 -> 3600 | G5: {=IFERROR((F5-INDEX($F:$F,MATCH($A5-1&$B5,$A:$A&$B:$B,0)))/INDEX($F:$F,MATCH($A5-1&$B5,$A:$A&$B:$B,0)),"")} | H5: =IF(A6=A5,(F6-F5)/F5,"") -> 0
A6: 2025 | B6: 5 | C6: =A6&"年"&B6&"月" -> 2025年5月 | D6: =SUMIFS(全学员总表!$F:$F, 全学员总表!$P:$P,$A6, 全学员总表!$Q:$Q,$B6) -> 2400 | E6: =SUM( SUMIFS(续费情况!$M:$M, 续费情况!$J:$J,">="&DATE($A6,$B6,1), 续费情况!$J:$J,"<="&EOMONTH(DATE($A6,$B6,1),0)), SUMIFS(续费情况!$Q:$Q, 续费情况!$N:$N,">="&DATE($A6,$B6,1), 续费情况!$N:$N,"<="&EOMONTH(DATE($A6,$B6,1),0)), SUMIFS(续费情况!$U:$U, 续费情况!$R:$R,">="&DATE($A6,$B6,1), 续费情况!$R:$R,"<="&EOMONTH(DATE($A6,$B6,1),0)) ) -> 1200 | F6: =D6+E6 -> 3600 | G6: {=IFERROR((F6-INDEX($F:$F,MATCH($A6-1&$B6,$A:$A&$B:$B,0)))/INDEX($F:$F,MATCH($A6-1&$B6,$A:$A&$B:$B,0)),"")} | H6: =IF(A7=A6,(F7-F6)/F6,"") -> 2.1666667
A7: 2025 | B7: 6 | C7: =A7&"年"&B7&"月" -> 2025年6月 | D7: =SUMIFS(全学员总表!$F:$F, 全学员总表!$P:$P,$A7, 全学员总表!$Q:$Q,$B7) -> 6600 | E7: =SUM( SUMIFS(续费情况!$M:$M, 续费情况!$J:$J,">="&DATE($A7,$B7,1), 续费情况!$J:$J,"<="&EOMONTH(DATE($A7,$B7,1),0)), SUMIFS(续费情况!$Q:$Q, 续费情况!$N:$N,">="&DATE($A7,$B7,1), 续费情况!$N:$N,"<="&EOMONTH(DATE($A7,$B7,1),0)), SUMIFS(续费情况!$U:$U, 续费情况!$R:$R,">="&DATE($A7,$B7,1), 续费情况!$R:$R,"<="&EOMONTH(DATE($A7,$B7,1),0)) ) -> 4800 | F7: =D7+E7 -> 11400 | G7: {=IFERROR((F7-INDEX($F:$F,MATCH($A7-1&$B7,$A:$A&$B:$B,0)))/INDEX($F:$F,MATCH($A7-1&$B7,$A:$A&$B:$B,0)),"")} | H7: =IF(A8=A7,(F8-F7)/F7,"") -> 0.47368421
A8: 2025 | B8: 7 | C8: =A8&"年"&B8&"月" -> 2025年7月 | D8: =SUMIFS(全学员总表!$F:$F, 全学员总表!$P:$P,$A8, 全学员总表!$Q:$Q,$B8) -> 10800 | E8: =SUM( SUMIFS(续费情况!$M:$M, 续费情况!$J:$J,">="&DATE($A8,$B8,1), 续费情况!$J:$J,"<="&EOMONTH(DATE($A8,$B8,1),0)), SUMIFS(续费情况!$Q:$Q, 续费情况!$N:$N,">="&DATE($A8,$B8,1), 续费情况!$N:$N,"<="&EOMONTH(DATE($A8,$B8,1),0)), SUMIFS(续费情况!$U:$U, 续费情况!$R:$R,">="&DATE($A8,$B8,1), 续费情况!$R:$R,"<="&EOMONTH(DATE($A8,$B8,1),0)) ) -> 6000 | F8: =D8+E8 -> 16800 | G8: {=IFERROR((F8-INDEX($F:$F,MATCH($A8-1&$B8,$A:$A&$B:$B,0)))/INDEX($F:$F,MATCH($A8-1&$B8,$A:$A&$B:$B,0)),"")} | H8: =IF(A9=A8,(F9-F8)/F8,"") -> -0.10714286
A9: 2025 | B9: 8 | C9: =A9&"年"&B9&"月" -> 2025年8月 | D9: =SUMIFS(全学员总表!$F:$F, 全学员总表!$P:$P,$A9, 全学员总表!$Q:$Q,$B9) -> 11400 | E9: =SUM( SUMIFS(续费情况!$M:$M, 续费情况!$J:$J,">="&DATE($A9,$B9,1), 续费情况!$J:$J,"<="&EOMONTH(DATE($A9,$B9,1),0)), SUMIFS(续费情况!$Q:$Q, 续费情况!$N:$N,">="&DATE($A9,$B9,1), 续费情况!$N:$N,"<="&EOMONTH(DATE($A9,$B9,1),0)), SUMIFS(续费情况!$U:$U, 续费情况!$R:$R,">="&DATE($A9,$B9,1), 续费情况!$R:$R,"<="&EOMONTH(DATE($A9,$B9,1),0)) ) -> 3600 | F9: =D9+E9 -> 15000 | G9: {=IFERROR((F9-INDEX($F:$F,MATCH($A9-1&$B9,$A:$A&$B:$B,0)))/INDEX($F:$F,MATCH($A9-1&$B9,$A:$A&$B:$B,0)),"")} | H9: =IF(A10=A9,(F10-F9)/F9,"") -> -0.2
A10: 2025 | B10: 9 | C10: =A10&"年"&B10&"月" -> 2025年9月 | D10: =SUMIFS(全学员总表!$F:$F, 全学员总表!$P:$P,$A10, 全学员总表!$Q:$Q,$B10) -> 6000 | E10: =SUM( SUMIFS(续费情况!$M:$M, 续费情况!$J:$J,">="&DATE($A10,$B10,1), 续费情况!$J:$J,"<="&EOMONTH(DATE($A10,$B10,1),0)), SUMIFS(续费情况!$Q:$Q, 续费情况!$N:$N,">="&DATE($A10,$B10,1), 续费情况!$N:$N,"<="&EOMONTH(DATE($A10,$B10,1),0)), SUMIFS(续费情况!$U:$U, 续费情况!$R:$R,">="&DATE($A10,$B10,1), 续费情况!$R:$R,"<="&EOMONTH(DATE($A10,$B10,1),0)) ) -> 6000 | F10: =D10+E10 -> 12000 | G10: {=IFERROR((F10-INDEX($F:$F,MATCH($A10-1&$B10,$A:$A&$B:$B,0)))/INDEX($F:$F,MATCH($A10-1&$B10,$A:$A&$B:$B,0)),"")} | H10: =IF(A11=A10,(F11-F10)/F10,"") -> -0.1
A11: 2025 | B11: 10 | C11: =A11&"年"&B11&"月" -> 2025年10月 | D11: =SUMIFS(全学员总表!$F:$F, 全学员总表!$P:$P,$A11, 全学员总表!$Q:$Q,$B11) -> 1200 | E11: =SUM( SUMIFS(续费情况!$M:$M, 续费情况!$J:$J,">="&DATE($A11,$B11,1), 续费情况!$J:$J,"<="&EOMONTH(DATE($A11,$B11,1),0)), SUMIFS(续费情况!$Q:$Q, 续费情况!$N:$N,">="&DATE($A11,$B11,1), 续费情况!$N:$N,"<="&EOMONTH(DATE($A11,$B11,1),0)), SUMIFS(续费情况!$U:$U, 续费情况!$R:$R,">="&DATE($A11,$B11,1), 续费情况!$R:$R,"<="&EOMONTH(DATE($A11,$B11,1),0)) ) -> 9600 | F11: =D11+E11 -> 10800 | G11: {=IFERROR((F11-INDEX($F:$F,MATCH($A11-1&$B11,$A:$A&$B:$B,0)))/INDEX($F:$F,MATCH($A11-1&$B11,$A:$A&$B:$B,0)),"")} | H11: =IF(A12=A11,(F12-F11)/F11,"") -> 0
A12: 2025 | B12: 11 | C12: =A12&"年"&B12&"月" -> 2025年11月 | D12: =SUMIFS(全学员总表!$F:$F, 全学员总表!$P:$P,$A12, 全学员总表!$Q:$Q,$B12) -> 0 | E12: =SUM( SUMIFS(续费情况!$M:$M, 续费情况!$J:$J,">="&DATE($A12,$B12,1), 续费情况!$J:$J,"<="&EOMONTH(DATE($A12,$B12,1),0)), SUMIFS(续费情况!$Q:$Q, 续费情况!$N:$N,">="&DATE($A12,$B12,1), 续费情况!$N:$N,"<="&EOMONTH(DATE($A12,$B12,1),0)), SUMIFS(续费情况!$U:$U, 续费情况!$R:$R,">="&DATE($A12,$B12,1), 续费情况!$R:$R,"<="&EOMONTH(DATE($A12,$B12,1),0)) ) -> 10800 | F12: =D12+E12 -> 10800 | G12: {=IFERROR((F12-INDEX($F:$F,MATCH($A12-1&$B12,$A:$A&$B:$B,0)))/INDEX($F:$F,MATCH($A12-1&$B12,$A:$A&$B:$B,0)),"")} | H12: =IF(A13=A12,(F13-F12)/F12,"") -> 0.16666667
A13: 2025 | B13: 12 | C13: =A13&"年"&B13&"月" -> 2025年12月 | D13: =SUMIFS(全学员总表!$F:$F, 全学员总表!$P:$P,$A13, 全学员总表!$Q:$Q,$B13) -> 0 | E13: =SUM( SUMIFS(续费情况!$M:$M, 续费情况!$J:$J,">="&DATE($A13,$B13,1), 续费情况!$J:$J,"<="&EOMONTH(DATE($A13,$B13,1),0)), SUMIFS(续费情况!$Q:$Q, 续费情况!$N:$N,">="&DATE($A13,$B13,1), 续费情况!$N:$N,"<="&EOMONTH(DATE($A13,$B13,1),0)), SUMIFS(续费情况!$U:$U, 续费情况!$R:$R,">="&DATE($A13,$B13,1), 续费情况!$R:$R,"<="&EOMONTH(DATE($A13,$B13,1),0)) ) -> 12600 | F13: =D13+E13 -> 12600 | G13: {=IFERROR((F13-INDEX($F:$F,MATCH($A13-1&$B13,$A:$A&$B:$B,0)))/INDEX($F:$F,MATCH($A13-1&$B13,$A:$A&$B:$B,0)),"")} | H13: =IF(A14=A13,(F14-F13)/F13,"")
A14: 2026 | B14: 1 | C14: =A14&"年"&B14&"月" -> 2026年1月 | D14: =SUMIFS(全学员总表!$F:$F, 全学员总表!$P:$P,$A14, 全学员总表!$Q:$Q,$B14) -> 0 | E14: =SUM( SUMIFS(续费情况!$M:$M, 续费情况!$J:$J,">="&DATE($A14,$B14,1), 续费情况!$J:$J,"<="&EOMONTH(DATE($A14,$B14,1),0)), SUMIFS(续费情况!$Q:$Q, 续费情况!$N:$N,">="&DATE($A14,$B14,1), 续费情况!$N:$N,"<="&EOMONTH(DATE($A14,$B14,1),0)), SUMIFS(续费情况!$U:$U, 续费情况!$R:$R,">="&DATE($A14,$B14,1), 续费情况!$R:$R,"<="&EOMONTH(DATE($A14,$B14,1),0)) ) -> 4200 | F14: =D14+E14 -> 4200 | G14: {=IFERROR((F14-INDEX($F:$F,MATCH($A14-1&$B14,$A:$A&$B:$B,0)))/INDEX($F:$F,MATCH($A14-1&$B14,$A:$A&$B:$B,0)),"")} -> -0.125 | H14: =IF(A15=A14,(F15-F14)/F14,"") -> -0.85714286
A15: 2026 | B15: 2 | C15: =A15&"年"&B15&"月" -> 2026年2月 | D15: =SUMIFS(全学员总表!$F:$F, 全学员总表!$P:$P,$A15, 全学员总表!$Q:$Q,$B15) -> 0 | E15: =SUM( SUMIFS(续费情况!$M:$M, 续费情况!$J:$J,">="&DATE($A15,$B15,1), 续费情况!$J:$J,"<="&EOMONTH(DATE($A15,$B15,1),0)), SUMIFS(续费情况!$Q:$Q, 续费情况!$N:$N,">="&DATE($A15,$B15,1), 续费情况!$N:$N,"<="&EOMONTH(DATE($A15,$B15,1),0)), SUMIFS(续费情况!$U:$U, 续费情况!$R:$R,">="&DATE($A15,$B15,1), 续费情况!$R:$R,"<="&EOMONTH(DATE($A15,$B15,1),0)) ) -> 600 | F15: =D15+E15 -> 600 | G15: {=IFERROR((F15-INDEX($F:$F,MATCH($A15-1&$B15,$A:$A&$B:$B,0)))/INDEX($F:$F,MATCH($A15-1&$B15,$A:$A&$B:$B,0)),"")} -> -0.88461538 | H15: =IF(A16=A15,(F16-F15)/F15,"") -> -1
A16: 2026 | B16: 3 | C16: =A16&"年"&B16&"月" -> 2026年3月 | D16: =SUMIFS(全学员总表!$F:$F, 全学员总表!$P:$P,$A16, 全学员总表!$Q:$Q,$B16) -> 0 | E16: =SUM( SUMIFS(续费情况!$M:$M, 续费情况!$J:$J,">="&DATE($A16,$B16,1), 续费情况!$J:$J,"<="&EOMONTH(DATE($A16,$B16,1),0)), SUMIFS(续费情况!$Q:$Q, 续费情况!$N:$N,">="&DATE($A16,$B16,1), 续费情况!$N:$N,"<="&EOMONTH(DATE($A16,$B16,1),0)), SUMIFS(续费情况!$U:$U, 续费情况!$R:$R,">="&DATE($A16,$B16,1), 续费情况!$R:$R,"<="&EOMONTH(DATE($A16,$B16,1),0)) ) -> 0 | F16: =D16+E16 -> 0 | G16: {=IFERROR((F16-INDEX($F:$F,MATCH($A16-1&$B16,$A:$A&$B:$B,0)))/INDEX($F:$F,MATCH($A16-1&$B16,$A:$A&$B:$B,0)),"")} -> -1
A17: 2026 | B17: 4 | C17: =A17&"年"&B17&"月" -> 2026年4月 | D17: =SUMIFS(全学员总表!$F:$F, 全学员总表!$P:$P,$A17, 全学员总表!$Q:$Q,$B17) -> 0 | E17: =SUM( SUMIFS(续费情况!$M:$M, 续费情况!$J:$J,">="&DATE($A17,$B17,1), 续费情况!$J:$J,"<="&EOMONTH(DATE($A17,$B17,1),0)), SUMIFS(续费情况!$Q:$Q, 续费情况!$N:$N,">="&DATE($A17,$B17,1), 续费情况!$N:$N,"<="&EOMONTH(DATE($A17,$B17,1),0)), SUMIFS(续费情况!$U:$U, 续费情况!$R:$R,">="&DATE($A17,$B17,1), 续费情况!$R:$R,"<="&EOMONTH(DATE($A17,$B17,1),0)) ) -> 0 | F17: =D17+E17 -> 0 | G17: {=IFERROR((F17-INDEX($F:$F,MATCH($A17-1&$B17,$A:$A&$B:$B,0)))/INDEX($F:$F,MATCH($A17-1&$B17,$A:$A&$B:$B,0)),"")} -> -1
A18: 2026 | B18: 5 | C18: =A18&"年"&B18&"月" -> 2026年5月 | D18: =SUMIFS(全学员总表!$F:$F, 全学员总表!$P:$P,$A18, 全学员总表!$Q:$Q,$B18) -> 0 | E18: =SUM( SUMIFS(续费情况!$M:$M, 续费情况!$J:$J,">="&DATE($A18,$B18,1), 续费情况!$J:$J,"<="&EOMONTH(DATE($A18,$B18,1),0)), SUMIFS(续费情况!$Q:$Q, 续费情况!$N:$N,">="&DATE($A18,$B18,1), 续费情况!$N:$N,"<="&EOMONTH(DATE($A18,$B18,1),0)), SUMIFS(续费情况!$U:$U, 续费情况!$R:$R,">="&DATE($A18,$B18,1), 续费情况!$R:$R,"<="&EOMONTH(DATE($A18,$B18,1),0)) ) -> 0 | F18: =D18+E18 -> 0 | G18: {=IFERROR((F18-INDEX($F:$F,MATCH($A18-1&$B18,$A:$A&$B:$B,0)))/INDEX($F:$F,MATCH($A18-1&$B18,$A:$A&$B:$B,0)),"")} -> -1

Sheet 学生情况报表
A1: =C4&"年"&H4&"月数据汇总" -> 2026年1月数据汇总
B4: 年份筛选： | C4: 2026 | G4: 月份筛选： | H4: 1
A5: 月累计：
B6: 月度总营收 | D6: 续费人数 | F6: 应续费人数 | H6: 续费率
B7: =SUMIFS(续费情况!I:I,续费情况!G:G,">="&DATE(C4,H4,1),续费情况!G:G,"<="&EOMONTH(DATE(C4,H4,1),0)) +SUMIFS(续费情况!M:M,续费情况!J:J,">="&DATE(C4,H4,1),续费情况!J:J,"<="&EOMONTH(DATE(C4,H4,1),0)) +SUMIFS(续费情况!Q:Q,续费情况!N:N,">="&DATE(C4,H4,1),续费情况!N:N,"<="&EOMONTH(DATE(C4,H4,1),0)) +SUMIFS(续费情况!U:U,续费情况!R:R,">="&DATE(C4,H4,1),续费情况!R:R,"<="&EOMONTH(DATE(C4,H4,1),0)) -> 4200 | D7: =COUNTIFS(续费情况!J:J,">="&DATE(C4,H4,1),续费情况!J:J,"<="&EOMONTH(DATE(C4,H4,1),0),续费情况!K:K,TRUE)+COUNTIFS(续费情况!N:N,">="&DATE(C4,H4,1),续费情况!N:N,"<="&EOMONTH(DATE(C4,H4,1),0),续费情况!O:O,TRUE)+COUNTIFS(续费情况!R:R,">="&DATE(C4,H4,1),续费情况!R:R,"<="&EOMONTH(DATE(C4,H4,1),0),续费情况!S:S,TRUE)+COUNTIFS(续费情况!V:V,">="&DATE(C4,H4,1),续费情况!V:V,"<="&EOMONTH(DATE(C4,H4,1),0),续费情况!W:W,TRUE) -> 5 | F7: =COUNTIFS(续费情况!J:J,">="&DATE(C4,H4,1),续费情况!J:J,"<="&EOMONTH(DATE(C4,H4,1),0))+COUNTIFS(续费情况!N:N,">="&DATE(C4,H4,1),续费情况!N:N,"<="&EOMONTH(DATE(C4,H4,1),0))+COUNTIFS(续费情况!R:R,">="&DATE(C4,H4,1),续费情况!R:R,"<="&EOMONTH(DATE(C4,H4,1),0))+COUNTIFS(续费情况!V:V,">="&DATE(C4,H4,1),续费情况!V:V,"<="&EOMONTH(DATE(C4,H4,1),0)) -> 7 | H7: =IFERROR(D7/F7,"-") -> 0.71428571
B8: 月度新签营收 | D8: 月度实收续费营收 | F8: Scratch 月度总营收 | H8: python月度总营收 | J8: C++月度总营收
B9: =SUMIFS(全学员总表!F:F,全学员总表!D:D,">="&DATE($C$4,$H$4,1),全学员总表!D:D,"<="&EOMONTH(DATE($C$4,$H$4,1),0)) -> 0 | D9: =SUMIFS(续费情况!M:M,续费情况!J:J,">="&DATE($C$4,$H$4,1),续费情况!J:J,"<="&EOMONTH(DATE($C$4,$H$4,1),0))+SUMIFS(续费情况!Q:Q,续费情况!N:N,">="&DATE($C$4,$H$4,1),续费情况!N:N,"<="&EOMONTH(DATE($C$4,$H$4,1),0))+SUMIFS(续费情况!U:U,续费情况!R:R,">="&DATE($C$4,$H$4,1),续费情况!R:R,"<="&EOMONTH(DATE($C$4,$H$4,1),0)) -> 4200 | F9: =SUMIFS(续费情况!I:I,续费情况!G:G,">="&DATE($C$4,$H$4,1),续费情况!G:G,"<="&EOMONTH(DATE($C$4,$H$4,1),0),续费情况!C:C,"scratch")+SUMIFS(续费情况!M:M,续费情况!J:J,">="&DATE($C$4,$H$4,1),续费情况!J:J,"<="&EOMONTH(DATE($C$4,$H$4,1),0),续费情况!C:C,"scratch")+SUMIFS(续费情况!Q:Q,续费情况!N:N,">="&DATE($C$4,$H$4,1),续费情况!N:N,"<="&EOMONTH(DATE($C$4,$H$4,1),0),续费情况!C:C,"scratch")+SUMIFS(续费情况!U:U,续费情况!R:R,">="&DATE($C$4,$H$4,1),续费情况!R:R,"<="&EOMONTH(DATE($C$4,$H$4,1),0),续费情况!C:C,"scratch") -> 2400 | H9: =SUMIFS(续费情况!I:I,续费情况!G:G,">="&DATE($C$4,$H$4,1),续费情况!G:G,"<="&EOMONTH(DATE($C$4,$H$4,1),0),续费情况!C:C,"Python")+SUMIFS(续费情况!M:M,续费情况!J:J,">="&DATE($C$4,$H$4,1),续费情况!J:J,"<="&EOMONTH(DATE($C$4,$H$4,1),0),续费情况!C:C,"Python")+SUMIFS(续费情况!Q:Q,续费情况!N:N,">="&DATE($C$4,$H$4,1),续费情况!N:N,"<="&EOMONTH(DATE($C$4,$H$4,1),0),续费情况!C:C,"Python")+SUMIFS(续费情况!U:U,续费情况!R:R,">="&DATE($C$4,$H$4,1),续费情况!R:R,"<="&EOMONTH(DATE($C$4,$H$4,1),0),续费情况!C:C,"Python") -> 0 | J9: =SUMIFS(续费情况!I:I,续费情况!G:G,">="&DATE($C$4,$H$4,1),续费情况!G:G,"<="&EOMONTH(DATE($C$4,$H$4,1),0),续费情况!C:C,"c++")+SUMIFS(续费情况!M:M,续费情况!J:J,">="&DATE($C$4,$H$4,1),续费情况!J:J,"<="&EOMONTH(DATE($C$4,$H$4,1),0),续费情况!C:C,"c++")+SUMIFS(续费情况!Q:Q,续费情况!N:N,">="&DATE($C$4,$H$4,1),续费情况!N:N,"<="&EOMONTH(DATE($C$4,$H$4,1),0),续费情况!C:C,"c++")+SUMIFS(续费情况!U:U,续费情况!R:R,">="&DATE($C$4,$H$4,1),续费情况!R:R,"<="&EOMONTH(DATE($C$4,$H$4,1),0),续费情况!C:C,"c++") -> 1800
A13: 姓名 | B13: 是否续费 | E13: Scratch课程总营收： | G13: =SUMIFS(全学员总表!O:O,全学员总表!C:C,"Scratch") -> 78200
A14: {=_xlfn._xlws.FILTER(续费情况!B2:B999, (((续费情况!J2:J999>=DATE(C4,H4,1))*(续费情况!J2:J999<=EOMONTH(DATE(C4,H4,1),0))) +(续费情况!N2:N999>=DATE(C4,H4,1))*(续费情况!N2:N999<=EOMONTH(DATE(C4,H4,1),0)) +(续费情况!R2:R999>=DATE(C4,H4,1))*(续费情况!R2:R999<=EOMONTH(DATE(C4,H4,1),0)) +(续费情况!V2:V999>=DATE(C4,H4,1))*(续费情况!V2:V999<=EOMONTH(DATE(C4,H4,1),0))>0),"")} -> 张锦程 | B14: =IF(A14="","",IFERROR(IF(COUNTIFS(续费情况!B:B,A14,续费情况!J:J,">="&DATE($C$4,$H$4,1),续费情况!J:J,"<="&EOMONTH(DATE($C$4,$H$4,1),0)),VLOOKUP(A14,续费情况!B:K,10,FALSE),IF(COUNTIFS(续费情况!B:B,A14,续费情况!N:N,">="&DATE($C$4,$H$4,1),续费情况!N:N,"<="&EOMONTH(DATE($C$4,$H$4,1),0)),VLOOKUP(A14,续费情况!B:O,14,FALSE),IF(COUNTIFS(续费情况!B:B,A14,续费情况!R:R,">="&DATE($C$4,$H$4,1),续费情况!R:R,"<="&EOMONTH(DATE($C$4,$H$4,1),0)),VLOOKUP(A14,续费情况!B:S,18,FALSE),VLOOKUP(A14,续费情况!B:W,22,FALSE)))),FALSE)) -> TRUE
A15: 张俊豪 | B15: =IF(A15="","",IFERROR(IF(COUNTIFS(续费情况!B:B,A15,续费情况!J:J,">="&DATE($C$4,$H$4,1),续费情况!J:J,"<="&EOMONTH(DATE($C$4,$H$4,1),0)),VLOOKUP(A15,续费情况!B:K,10,FALSE),IF(COUNTIFS(续费情况!B:B,A15,续费情况!N:N,">="&DATE($C$4,$H$4,1),续费情况!N:N,"<="&EOMONTH(DATE($C$4,$H$4,1),0)),VLOOKUP(A15,续费情况!B:O,14,FALSE),IF(COUNTIFS(续费情况!B:B,A15,续费情况!R:R,">="&DATE($C$4,$H$4,1),续费情况!R:R,"<="&EOMONTH(DATE($C$4,$H$4,1),0)),VLOOKUP(A15,续费情况!B:S,18,FALSE),VLOOKUP(A15,续费情况!B:W,22,FALSE)))),FALSE)) -> TRUE
A16: 李若溪 | B16: =IF(A16="","",IFERROR(IF(COUNTIFS(续费情况!B:B,A16,续费情况!J:J,">="&DATE($C$4,$H$4,1),续费情况!J:J,"<="&EOMONTH(DATE($C$4,$H$4,1),0)),VLOOKUP(A16,续费情况!B:K,10,FALSE),IF(COUNTIFS(续费情况!B:B,A16,续费情况!N:N,">="&DATE($C$4,$H$4,1),续费情况!N:N,"<="&EOMONTH(DATE($C$4,$H$4,1),0)),VLOOKUP(A16,续费情况!B:O,14,FALSE),IF(COUNTIFS(续费情况!B:B,A16,续费情况!R:R,">="&DATE($C$4,$H$4,1),续费情况!R:R,"<="&EOMONTH(DATE($C$4,$H$4,1),0)),VLOOKUP(A16,续费情况!B:S,18,FALSE),VLOOKUP(A16,续费情况!B:W,22,FALSE)))),FALSE)) -> FALSE | E16: Python课程总营收： | G16: =SUMIFS(全学员总表!O:O,全学员总表!C:C,"Python") -> 18000
A17: 黄奕凡 | B17: =IF(A17="","",IFERROR(IF(COUNTIFS(续费情况!B:B,A17,续费情况!J:J,">="&DATE($C$4,$H$4,1),续费情况!J:J,"<="&EOMONTH(DATE($C$4,$H$4,1),0)),VLOOKUP(A17,续费情况!B:K,10,FALSE),IF(COUNTIFS(续费情况!B:B,A17,续费情况!N:N,">="&DATE($C$4,$H$4,1),续费情况!N:N,"<="&EOMONTH(DATE($C$4,$H$4,1),0)),VLOOKUP(A17,续费情况!B:O,14,FALSE),IF(COUNTIFS(续费情况!B:B,A17,续费情况!R:R,">="&DATE($C$4,$H$4,1),续费情况!R:R,"<="&EOMONTH(DATE($C$4,$H$4,1),0)),VLOOKUP(A17,续费情况!B:S,18,FALSE),VLOOKUP(A17,续费情况!B:W,22,FALSE)))),FALSE)) -> FALSE
A18: 胡星朗 | B18: =IF(A18="","",IFERROR(IF(COUNTIFS(续费情况!B:B,A18,续费情况!J:J,">="&DATE($C$4,$H$4,1),续费情况!J:J,"<="&EOMONTH(DATE($C$4,$H$4,1),0)),VLOOKUP(A18,续费情况!B:K,10,FALSE),IF(COUNTIFS(续费情况!B:B,A18,续费情况!N:N,">="&DATE($C$4,$H$4,1),续费情况!N:N,"<="&EOMONTH(DATE($C$4,$H$4,1),0)),VLOOKUP(A18,续费情况!B:O,14,FALSE),IF(COUNTIFS(续费情况!B:B,A18,续费情况!R:R,">="&DATE($C$4,$H$4,1),续费情况!R:R,"<="&EOMONTH(DATE($C$4,$H$4,1),0)),VLOOKUP(A18,续费情况!B:S,18,FALSE),VLOOKUP(A18,续费情况!B:W,22,FALSE)))),FALSE)) -> TRUE
A19: 林凯瑞 | B19: =IF(A19="","",IFERROR(IF(COUNTIFS(续费情况!B:B,A19,续费情况!J:J,">="&DATE($C$4,$H$4,1),续费情况!J:J,"<="&EOMONTH(DATE($C$4,$H$4,1),0)),VLOOKUP(A19,续费情况!B:K,10,FALSE),IF(COUNTIFS(续费情况!B:B,A19,续费情况!N:N,">="&DATE($C$4,$H$4,1),续费情况!N:N,"<="&EOMONTH(DATE($C$4,$H$4,1),0)),VLOOKUP(A19,续费情况!B:O,14,FALSE),IF(COUNTIFS(续费情况!B:B,A19,续费情况!R:R,">="&DATE($C$4,$H$4,1),续费情况!R:R,"<="&EOMONTH(DATE($C$4,$H$4,1),0)),VLOOKUP(A19,续费情况!B:S,18,FALSE),VLOOKUP(A19,续费情况!B:W,22,FALSE)))),FALSE)) -> TRUE | E19: c++课程总营收： | G19: =SUMIFS(全学员总表!O:O,全学员总表!C:C,"c++") -> 18800
A20: 周芷晴 | B20: =IF(A20="","",IFERROR(IF(COUNTIFS(续费情况!B:B,A20,续费情况!J:J,">="&DATE($C$4,$H$4,1),续费情况!J:J,"<="&EOMONTH(DATE($C$4,$H$4,1),0)),VLOOKUP(A20,续费情况!B:K,10,FALSE),IF(COUNTIFS(续费情况!B:B,A20,续费情况!N:N,">="&DATE($C$4,$H$4,1),续费情况!N:N,"<="&EOMONTH(DATE($C$4,$H$4,1),0)),VLOOKUP(A20,续费情况!B:O,14,FALSE),IF(COUNTIFS(续费情况!B:B,A20,续费情况!R:R,">="&DATE($C$4,$H$4,1),续费情况!R:R,"<="&EOMONTH(DATE($C$4,$H$4,1),0)),VLOOKUP(A20,续费情况!B:S,18,FALSE),VLOOKUP(A20,续费情况!B:W,22,FALSE)))),FALSE)) -> TRUE
B21: =IF(A21="","",IFERROR(IF(COUNTIFS(续费情况!B:B,A21,续费情况!J:J,">="&DATE($C$4,$H$4,1),续费情况!J:J,"<="&EOMONTH(DATE($C$4,$H$4,1),0)),VLOOKUP(A21,续费情况!B:K,10,FALSE),IF(COUNTIFS(续费情况!B:B,A21,续费情况!N:N,">="&DATE($C$4,$H$4,1),续费情况!N:N,"<="&EOMONTH(DATE($C$4,$H$4,1),0)),VLOOKUP(A21,续费情况!B:O,14,FALSE),IF(COUNTIFS(续费情况!B:B,A21,续费情况!R:R,">="&DATE($C$4,$H$4,1),续费情况!R:R,"<="&EOMONTH(DATE($C$4,$H$4,1),0)),VLOOKUP(A21,续费情况!B:S,18,FALSE),VLOOKUP(A21,续费情况!B:W,22,FALSE)))),FALSE))
B22: =IF(A22="","",IFERROR(IF(COUNTIFS(续费情况!B:B,A22,续费情况!J:J,">="&DATE($C$4,$H$4,1),续费情况!J:J,"<="&EOMONTH(DATE($C$4,$H$4,1),0)),VLOOKUP(A22,续费情况!B:K,10,FALSE),IF(COUNTIFS(续费情况!B:B,A22,续费情况!N:N,">="&DATE($C$4,$H$4,1),续费情况!N:N,"<="&EOMONTH(DATE($C$4,$H$4,1),0)),VLOOKUP(A22,续费情况!B:O,14,FALSE),IF(COUNTIFS(续费情况!B:B,A22,续费情况!R:R,">="&DATE($C$4,$H$4,1),续费情况!R:R,"<="&EOMONTH(DATE($C$4,$H$4,1),0)),VLOOKUP(A22,续费情况!B:S,18,FALSE),VLOOKUP(A22,续费情况!B:W,22,FALSE)))),FALSE)) | E22: 总营收： | G22: =G13+G16+G19 -> 115000
B23: =IF(A23="","",IFERROR(IF(COUNTIFS(续费情况!B:B,A23,续费情况!J:J,">="&DATE($C$4,$H$4,1),续费情况!J:J,"<="&EOMONTH(DATE($C$4,$H$4,1),0)),VLOOKUP(A23,续费情况!B:K,10,FALSE),IF(COUNTIFS(续费情况!B:B,A23,续费情况!N:N,">="&DATE($C$4,$H$4,1),续费情况!N:N,"<="&EOMONTH(DATE($C$4,$H$4,1),0)),VLOOKUP(A23,续费情况!B:O,14,FALSE),IF(COUNTIFS(续费情况!B:B,A23,续费情况!R:R,">="&DATE($C$4,$H$4,1),续费情况!R:R,"<="&EOMONTH(DATE($C$4,$H$4,1),0)),VLOOKUP(A23,续费情况!B:S,18,FALSE),VLOOKUP(A23,续费情况!B:W,22,FALSE)))),FALSE))
B24: =IF(A24="","",IFERROR(IF(COUNTIFS(续费情况!B:B,A24,续费情况!J:J,">="&DATE($C$4,$H$4,1),续费情况!J:J,"<="&EOMONTH(DATE($C$4,$H$4,1),0)),VLOOKUP(A24,续费情况!B:K,10,FALSE),IF(COUNTIFS(续费情况!B:B,A24,续费情况!N:N,">="&DATE($C$4,$H$4,1),续费情况!N:N,"<="&EOMONTH(DATE($C$4,$H$4,1),0)),VLOOKUP(A24,续费情况!B:O,14,FALSE),IF(COUNTIFS(续费情况!B:B,A24,续费情况!R:R,">="&DATE($C$4,$H$4,1),续费情况!R:R,"<="&EOMONTH(DATE($C$4,$H$4,1),0)),VLOOKUP(A24,续费情况!B:S,18,FALSE),VLOOKUP(A24,续费情况!B:W,22,FALSE)))),FALSE))
B25: =IF(A25="","",IFERROR(IF(COUNTIFS(续费情况!B:B,A25,续费情况!J:J,">="&DATE($C$4,$H$4,1),续费情况!J:J,"<="&EOMONTH(DATE($C$4,$H$4,1),0)),VLOOKUP(A25,续费情况!B:K,10,FALSE),IF(COUNTIFS(续费情况!B:B,A25,续费情况!N:N,">="&DATE($C$4,$H$4,1),续费情况!N:N,"<="&EOMONTH(DATE($C$4,$H$4,1),0)),VLOOKUP(A25,续费情况!B:O,14,FALSE),IF(COUNTIFS(续费情况!B:B,A25,续费情况!R:R,">="&DATE($C$4,$H$4,1),续费情况!R:R,"<="&EOMONTH(DATE($C$4,$H$4,1),0)),VLOOKUP(A25,续费情况!B:S,18,FALSE),VLOOKUP(A25,续费情况!B:W,22,FALSE)))),FALSE))
B26: =IF(A26="","",IFERROR(IF(COUNTIFS(续费情况!B:B,A26,续费情况!J:J,">="&DATE($C$4,$H$4,1),续费情况!J:J,"<="&EOMONTH(DATE($C$4,$H$4,1),0)),VLOOKUP(A26,续费情况!B:K,10,FALSE),IF(COUNTIFS(续费情况!B:B,A26,续费情况!N:N,">="&DATE($C$4,$H$4,1),续费情况!N:N,"<="&EOMONTH(DATE($C$4,$H$4,1),0)),VLOOKUP(A26,续费情况!B:O,14,FALSE),IF(COUNTIFS(续费情况!B:B,A26,续费情况!R:R,">="&DATE($C$4,$H$4,1),续费情况!R:R,"<="&EOMONTH(DATE($C$4,$H$4,1),0)),VLOOKUP(A26,续费情况!B:S,18,FALSE),VLOOKUP(A26,续费情况!B:W,22,FALSE)))),FALSE))
B27: =IF(A27="","",IFERROR(IF(COUNTIFS(续费情况!B:B,A27,续费情况!J:J,">="&DATE($C$4,$H$4,1),续费情况!J:J,"<="&EOMONTH(DATE($C$4,$H$4,1),0)),VLOOKUP(A27,续费情况!B:K,10,FALSE),IF(COUNTIFS(续费情况!B:B,A27,续费情况!N:N,">="&DATE($C$4,$H$4,1),续费情况!N:N,"<="&EOMONTH(DATE($C$4,$H$4,1),0)),VLOOKUP(A27,续费情况!B:O,14,FALSE),IF(COUNTIFS(续费情况!B:B,A27,续费情况!R:R,">="&DATE($C$4,$H$4,1),续费情况!R:R,"<="&EOMONTH(DATE($C$4,$H$4,1),0)),VLOOKUP(A27,续费情况!B:S,18,FALSE),VLOOKUP(A27,续费情况!B:W,22,FALSE)))),FALSE))
B28: =IF(A28="","",IFERROR(IF(COUNTIFS(续费情况!B:B,A28,续费情况!J:J,">="&DATE($C$4,$H$4,1),续费情况!J:J,"<="&EOMONTH(DATE($C$4,$H$4,1),0)),VLOOKUP(A28,续费情况!B:K,10,FALSE),IF(COUNTIFS(续费情况!B:B,A28,续费情况!N:N,">="&DATE($C$4,$H$4,1),续费情况!N:N,"<="&EOMONTH(DATE($C$4,$H$4,1),0)),VLOOKUP(A28,续费情况!B:O,14,FALSE),IF(COUNTIFS(续费情况!B:B,A28,续费情况!R:R,">="&DATE($C$4,$H$4,1),续费情况!R:R,"<="&EOMONTH(DATE($C$4,$H$4,1),0)),VLOOKUP(A28,续费情况!B:S,18,FALSE),VLOOKUP(A28,续费情况!B:W,22,FALSE)))),FALSE))
B29: =IF(A29="","",IFERROR(IF(COUNTIFS(续费情况!B:B,A29,续费情况!J:J,">="&DATE($C$4,$H$4,1),续费情况!J:J,"<="&EOMONTH(DATE($C$4,$H$4,1),0)),VLOOKUP(A29,续费情况!B:K,10,FALSE),IF(COUNTIFS(续费情况!B:B,A29,续费情况!N:N,">="&DATE($C$4,$H$4,1),续费情况!N:N,"<="&EOMONTH(DATE($C$4,$H$4,1),0)),VLOOKUP(A29,续费情况!B:O,14,FALSE),IF(COUNTIFS(续费情况!B:B,A29,续费情况!R:R,">="&DATE($C$4,$H$4,1),续费情况!R:R,"<="&EOMONTH(DATE($C$4,$H$4,1),0)),VLOOKUP(A29,续费情况!B:S,18,FALSE),VLOOKUP(A29,续费情况!B:W,22,FALSE)))),FALSE))
B30: =IF(A30="","",IFERROR(IF(COUNTIFS(续费情况!B:B,A30,续费情况!J:J,">="&DATE($C$4,$H$4,1),续费情况!J:J,"<="&EOMONTH(DATE($C$4,$H$4,1),0)),VLOOKUP(A30,续费情况!B:K,10,FALSE),IF(COUNTIFS(续费情况!B:B,A30,续费情况!N:N,">="&DATE($C$4,$H$4,1),续费情况!N:N,"<="&EOMONTH(DATE($C$4,$H$4,1),0)),VLOOKUP(A30,续费情况!B:O,14,FALSE),IF(COUNTIFS(续费情况!B:B,A30,续费情况!R:R,">="&DATE($C$4,$H$4,1),续费情况!R:R,"<="&EOMONTH(DATE($C$4,$H$4,1),0)),VLOOKUP(A30,续费情况!B:S,18,FALSE),VLOOKUP(A30,续费情况!B:W,22,FALSE)))),FALSE))
B31: =IF(A31="","",IFERROR(IF(COUNTIFS(续费情况!B:B,A31,续费情况!J:J,">="&DATE($C$4,$H$4,1),续费情况!J:J,"<="&EOMONTH(DATE($C$4,$H$4,1),0)),VLOOKUP(A31,续费情况!B:K,10,FALSE),IF(COUNTIFS(续费情况!B:B,A31,续费情况!N:N,">="&DATE($C$4,$H$4,1),续费情况!N:N,"<="&EOMONTH(DATE($C$4,$H$4,1),0)),VLOOKUP(A31,续费情况!B:O,14,FALSE),IF(COUNTIFS(续费情况!B:B,A31,续费情况!R:R,">="&DATE($C$4,$H$4,1),续费情况!R:R,"<="&EOMONTH(DATE($C$4,$H$4,1),0)),VLOOKUP(A31,续费情况!B:S,18,FALSE),VLOOKUP(A31,续费情况!B:W,22,FALSE)))),FALSE))

Sheet 学生基本信息
A1: 学员 ID | B1: 姓名 | C1: 语言 | D1: 报名时间 | E1: 报名课时 | F1: 缴费金额 | G1: 备注 | H1: 学生情况
A2: 1 | B2: 陈宇轩 | C2: scratch | D2: 45676 | E2: 12 | F2: =E2*100 -> 1200
A3: 2 | B3: 李浩泽 | C3: Python | D3: 45682 | E3: 24 | F3: 2400
A4: 3 | B4: 王梓航 | C4: scratch | D4: 45682 | E4: 12 | F4: =E4*100 -> 1200
A5: 4 | B5: 张锦程 | C5: scratch | D5: 45691 | E5: 24 | F5: 2000 | G5: 两人同时报名
A6: 5 | B6: 张俊豪 | C6: c++ | D6: 45691 | E6: 24 | F6: 2000 | G6: 两人同时报名
A7: 6 | B7: 李若溪 | C7: scratch | D7: 45703 | E7: 12 | F7: =E7*100 -> 1200
A8: 7 | B8: 周思远 | C8: scratch | D8: 45725 | E8: 12 | F8: =E8*100 -> 1200
A9: 8 | B9: 吴嘉硕 | C9: scratch | D9: 45730 | E9: 12 | F9: =E9*100 -> 1200
A10: 9 | B10: 郑博文 | C10: scratch | D10: 45739 | E10: 12 | F10: =E10*100 -> 1200
A11: 10 | B11: 骆思玥 | C11: scratch | D11: 45753 | E11: 12 | F11: =E11*100 -> 1200
A12: 11 | B12: 黄奕凡 | C12: scratch | D12: 45801 | E12: 24 | F12: =E12*100 -> 2400
A13: 12 | B13: 王语桐 | C13: scratch | D13: 45816 | E13: 36 | F13: 3000 | G13: 连报
A14: 13 | B14: 张欣瑶 | C14: scratch | D14: 45829 | E14: 24 | F14: =E14*100 -> 2400
A15: 14 | B15: 孙靖宇 | C15: Python | D15: 45837 | E15: 12 | F15: =E15*100 -> 1200
A16: 15 | B16: 马睿辰 | C16: Python | D16: 45844 | E16: 12 | F16: =E16*100 -> 1200
A17: 16 | B17: 刘梓萱 | C17: scratch | D17: 45849 | E17: 12 | F17: =E17*100 -> 1200
A18: 17 | B18: 朱泽宇 | C18: scratch | D18: 45849 | E18: 12 | F18: =E18*100 -> 1200
A19: 18 | B19: 陈舒然 | C19: scratch | D19: 45851 | E19: 24 | F19: =E19*100 -> 2400
A20: 19 | B20: 胡星朗 | C20: scratch | D20: 45857 | E20: 24 | F20: =E20*100 -> 2400
A21: 20 | B21: 林凯瑞 | C21: scratch | D21: 45858 | E21: 24 | F21: =E21*100 -> 2400
A22: 21 | B22: 周芷晴 | C22: c++ | D22: 45871 | E22: 12 | F22: =E22*100 -> 1200
A23: 22 | B23: 郭彦彬 | C23: c++ | D23: 45872 | E23: 36 | F23: 3000 | G23: 连报
A24: 23 | B24: 吴佳妮 | C24: c++ | D24: 45886 | E24: 12 | F24: =E24*100 -> 1200
A25: 24 | B25: 郑雨茉 | C25: scratch | D25: 45886 | E25: 12 | F25: =E25*100 -> 1200
A26: 25 | B26: 宋启恒 | C26: c++ | D26: 45891 | E26: 24 | F26: =E26*100 -> 2400
A27: 26 | B27: 黄诗涵 | C27: Python | D27: 45892 | E27: 12 | F27: =E27*100 -> 1200
A28: 27 | B28: 苏一诺 | C28: c++ | D28: 45898 | E28: 12 | F28: =E28*100 -> 1200
A29: 28 | B29: 韩沐阳 | C29: Python | D29: 45907 | E29: 24 | F29: =E29*100 -> 2400
A30: 29 | B30: 曹硕霖 | C30: scratch | D30: 45903 | E30: 12 | F30: =E30*100 -> 1200
A31: 30 | B31: 叶静怡 | C31: scratch | D31: 45911 | E31: 12 | F31: =E31*100 -> 1200
A32: 31 | B32: 陶沐汐 | C32: scratch | D32: 45930 | E32: 12 | F32: =E32*100 -> 1200
A33: 32 | B33: 邓崇安 | C33: scratch | D33: 45932 | E33: 12 | F33: =E33*100 -> 1200 | G33: 二年级，后面要学py

Sheet 续费情况
A1: 学员 ID | B1: 姓名 | C1: 语言 | D1: CPA考级结果 | E1: 电子学会考级结果 | F1: CCF-GESP考级结果 | G1: 报名月份 | H1: 报名课时 | I1: 缴费金额 | J1: 续费时间 | K1: 是否续费 | L1: 续费课时 | M1: 续费金额 | N1: 续费时间 | O1: 是否续费 | P1: 续费课时 | Q1: 续费金额 | R1: 续费时间 | S1: 是否续费 | T1: 续费课时 | U1: 续费金额 | V1: 续费时间 | W1: 是否续费
A2: 1 | B2: 陈宇轩 | C2: scratch | D2: =IF(VLOOKUP($A2,学生考级成绩!$A:$E,4,0)=0,"",VLOOKUP($A2,学生考级成绩!$A:$E,4,0)) -> 二级 | E2: =IF(VLOOKUP($A2,学生考级成绩!$A:$E,5,0)=0,"",VLOOKUP($A2,学生考级成绩!$A:$E,5,0)) | F2: =IF(VLOOKUP($A2,学生考级成绩!$A:$F,6,0)=0,"",VLOOKUP($A2,学生考级成绩!$A:$F,6,0)) | G2: 45676 | H2: 12 | I2: =H2*100 -> 1200 | J2: =G2+H2*7 -> 45760 | K2: TRUE | L2: 12 | M2: =IF(K2=TRUE,L2*100,0) -> 1200 | N2: =IF(K2=TRUE,J2+L2*7,"") -> 45844 | O2: TRUE | P2: 12 | Q2: =IF(O2=TRUE,P2*100,0) -> 1200 | R2: =IF(O2=TRUE,N2+P2*7,"") -> 45928 | S2: TRUE | T2: 12 | U2: =IF(S2=TRUE,T2*100,0) -> 1200 | V2: =IF(S2=TRUE,R2+T2*7,"") -> 46012 | W2: FALSE
A3: 2 | B3: 李浩泽 | C3: Python | D3: =IF(VLOOKUP($A3,学生考级成绩!$A:$E,4,0)=0,"",VLOOKUP($A3,学生考级成绩!$A:$E,4,0)) | E3: =IF(VLOOKUP($A3,学生考级成绩!$A:$E,5,0)=0,"",VLOOKUP($A3,学生考级成绩!$A:$E,5,0)) -> 四级 | F3: =IF(VLOOKUP($A3,学生考级成绩!$A:$F,6,0)=0,"",VLOOKUP($A3,学生考级成绩!$A:$F,6,0)) | G3: 45682 | H3: 24 | I3: 2400 | J3: =G3+H3*7 -> 45850 | K3: TRUE | L3: 12 | M3: =IF(K3=TRUE,L3*100,0) -> 1200 | N3: =IF(K3=TRUE,J3+L3*7,"") -> 45934 | O3: TRUE | P3: 12 | Q3: =IF(O3=TRUE,P3*100,0) -> 1200 | R3: =IF(O3=TRUE,N3+P3*7,"") -> 46018 | S3: TRUE | T3: 12 | U3: =IF(S3=TRUE,T3*100,0) -> 1200 | V3: =IF(S3=TRUE,R3+T3*7,"") -> 46102 | W3: FALSE
A4: 3 | B4: 王梓航 | C4: scratch | D4: =IF(VLOOKUP($A4,学生考级成绩!$A:$E,4,0)=0,"",VLOOKUP($A4,学生考级成绩!$A:$E,4,0)) -> 二级 | E4: =IF(VLOOKUP($A4,学生考级成绩!$A:$E,5,0)=0,"",VLOOKUP($A4,学生考级成绩!$A:$E,5,0)) | F4: =IF(VLOOKUP($A4,学生考级成绩!$A:$F,6,0)=0,"",VLOOKUP($A4,学生考级成绩!$A:$F,6,0)) | G4: 45682 | H4: 12 | I4: =H4*100 -> 1200 | J4: =G4+H4*7 -> 45766 | K4: TRUE | L4: 12 | M4: =IF(K4=TRUE,L4*100,0) -> 1200 | N4: =IF(K4=TRUE,J4+L4*7,"") -> 45850 | O4: TRUE | P4: 12 | Q4: =IF(O4=TRUE,P4*100,0) -> 1200 | R4: =IF(O4=TRUE,N4+P4*7,"") -> 45934 | S4: TRUE | T4: 12 | U4: =IF(S4=TRUE,T4*100,0) -> 1200 | V4: =IF(S4=TRUE,R4+T4*7,"") -> 46018 | W4: FALSE
A5: 4 | B5: 张锦程 | C5: scratch | D5: =IF(VLOOKUP($A5,学生考级成绩!$A:$E,4,0)=0,"",VLOOKUP($A5,学生考级成绩!$A:$E,4,0)) -> 二级 | E5: =IF(VLOOKUP($A5,学生考级成绩!$A:$E,5,0)=0,"",VLOOKUP($A5,学生考级成绩!$A:$E,5,0)) | F5: =IF(VLOOKUP($A5,学生考级成绩!$A:$F,6,0)=0,"",VLOOKUP($A5,学生考级成绩!$A:$F,6,0)) | G5: 45691 | H5: 24 | I5: 2000 | J5: =G5+H5*7 -> 45859 | K5: TRUE | L5: 12 | M5: =IF(K5=TRUE,L5*100,0) -> 1200 | N5: =IF(K5=TRUE,J5+L5*7,"") -> 45943 | O5: TRUE | P5: 12 | Q5: =IF(O5=TRUE,P5*100,0) -> 1200 | R5: =IF(O5=TRUE,N5+P5*7,"") -> 46027 | S5: TRUE | T5: 12 | U5: =IF(S5=TRUE,T5*100,0) -> 1200 | V5: =IF(S5=TRUE,R5+T5*7,"") -> 46111 | W5: FALSE
A6: 5 | B6: 张俊豪 | C6: c++ | D6: =IF(VLOOKUP($A6,学生考级成绩!$A:$E,4,0)=0,"",VLOOKUP($A6,学生考级成绩!$A:$E,4,0)) | E6: =IF(VLOOKUP($A6,学生考级成绩!$A:$E,5,0)=0,"",VLOOKUP($A6,学生考级成绩!$A:$E,5,0)) | F6: =IF(VLOOKUP($A6,学生考级成绩!$A:$F,6,0)=0,"",VLOOKUP($A6,学生考级成绩!$A:$F,6,0)) -> 三级 | G6: 45691 | H6: 24 | I6: 2000 | J6: =G6+H6*7 -> 45859 | K6: TRUE | L6: 12 | M6: =IF(K6=TRUE,L6*100,0) -> 1200 | N6: =IF(K6=TRUE,J6+L6*7,"") -> 45943 | O6: TRUE | P6: 12 | Q6: =IF(O6=TRUE,P6*100,0) -> 1200 | R6: =IF(O6=TRUE,N6+P6*7,"") -> 46027 | S6: TRUE | T6: 12 | U6: =IF(S6=TRUE,T6*100,0) -> 1200 | V6: =IF(S6=TRUE,R6+T6*7,"") -> 46111 | W6: FALSE
A7: 6 | B7: 李若溪 | C7: scratch | D7: =IF(VLOOKUP($A7,学生考级成绩!$A:$E,4,0)=0,"",VLOOKUP($A7,学生考级成绩!$A:$E,4,0)) -> 二级 | E7: =IF(VLOOKUP($A7,学生考级成绩!$A:$E,5,0)=0,"",VLOOKUP($A7,学生考级成绩!$A:$E,5,0)) | F7: =IF(VLOOKUP($A7,学生考级成绩!$A:$F,6,0)=0,"",VLOOKUP($A7,学生考级成绩!$A:$F,6,0)) | G7: 45703 | H7: 12 | I7: =H7*100 -> 1200 | J7: =G7+H7*7 -> 45787 | K7: TRUE | L7: 12 | M7: =IF(K7=TRUE,L7*100,0) -> 1200 | N7: =IF(K7=TRUE,J7+L7*7,"") -> 45871 | O7: TRUE | P7: 12 | Q7: =IF(O7=TRUE,P7*100,0) -> 1200 | R7: =IF(O7=TRUE,N7+P7*7,"") -> 45955 | S7: TRUE | T7: 12 | U7: =IF(S7=TRUE,T7*100,0) -> 1200 | V7: =IF(S7=TRUE,R7+T7*7,"") -> 46039 | W7: FALSE
A8: 7 | B8: 周思远 | C8: scratch | D8: =IF(VLOOKUP($A8,学生考级成绩!$A:$E,4,0)=0,"",VLOOKUP($A8,学生考级成绩!$A:$E,4,0)) -> 二级 | E8: =IF(VLOOKUP($A8,学生考级成绩!$A:$E,5,0)=0,"",VLOOKUP($A8,学生考级成绩!$A:$E,5,0)) | F8: =IF(VLOOKUP($A8,学生考级成绩!$A:$F,6,0)=0,"",VLOOKUP($A8,学生考级成绩!$A:$F,6,0)) | G8: 45725 | H8: 12 | I8: =H8*100 -> 1200 | J8: =G8+H8*7 -> 45809 | K8: TRUE | L8: 12 | M8: =IF(K8=TRUE,L8*100,0) -> 1200 | N8: =IF(K8=TRUE,J8+L8*7,"") -> 45893 | O8: TRUE | P8: 12 | Q8: =IF(O8=TRUE,P8*100,0) -> 1200 | R8: =IF(O8=TRUE,N8+P8*7,"") -> 45977 | S8: TRUE | T8: 12 | U8: =IF(S8=TRUE,T8*100,0) -> 1200 | V8: =IF(S8=TRUE,R8+T8*7,"") -> 46061 | W8: FALSE
A9: 8 | B9: 吴嘉硕 | C9: scratch | D9: =IF(VLOOKUP($A9,学生考级成绩!$A:$E,4,0)=0,"",VLOOKUP($A9,学生考级成绩!$A:$E,4,0)) -> 二级 | E9: =IF(VLOOKUP($A9,学生考级成绩!$A:$E,5,0)=0,"",VLOOKUP($A9,学生考级成绩!$A:$E,5,0)) | F9: =IF(VLOOKUP($A9,学生考级成绩!$A:$F,6,0)=0,"",VLOOKUP($A9,学生考级成绩!$A:$F,6,0)) | G9: 45730 | H9: 12 | I9: =H9*100 -> 1200 | J9: =G9+H9*7 -> 45814 | K9: TRUE | L9: 12 | M9: =IF(K9=TRUE,L9*100,0) -> 1200 | N9: =IF(K9=TRUE,J9+L9*7,"") -> 45898 | O9: TRUE | P9: 12 | Q9: =IF(O9=TRUE,P9*100,0) -> 1200 | R9: =IF(O9=TRUE,N9+P9*7,"") -> 45982 | S9: TRUE | T9: 12 | U9: =IF(S9=TRUE,T9*100,0) -> 1200 | V9: =IF(S9=TRUE,R9+T9*7,"") -> 46066 | W9: FALSE
A10: 9 | B10: 郑博文 | C10: scratch | D10: =IF(VLOOKUP($A10,学生考级成绩!$A:$E,4,0)=0,"",VLOOKUP($A10,学生考级成绩!$A:$E,4,0)) -> 一级 | E10: =IF(VLOOKUP($A10,学生考级成绩!$A:$E,5,0)=0,"",VLOOKUP($A10,学生考级成绩!$A:$E,5,0)) | F10: =IF(VLOOKUP($A10,学生考级成绩!$A:$F,6,0)=0,"",VLOOKUP($A10,学生考级成绩!$A:$F,6,0)) | G10: 45739 | H10: 12 | I10: =H10*100 -> 1200 | J10: =G10+H10*7 -> 45823 | K10: TRUE | L10: 12 | M10: =IF(K10=TRUE,L10*100,0) -> 1200 | N10: =IF(K10=TRUE,J10+L10*7,"") -> 45907 | O10: TRUE | P10: 12 | Q10: =IF(O10=TRUE,P10*100,0) -> 1200 | R10: =IF(O10=TRUE,N10+P10*7,"") -> 45991 | S10: TRUE | T10: 12 | U10: =IF(S10=TRUE,T10*100,0) -> 1200 | V10: =IF(S10=TRUE,R10+T10*7,"") -> 46075 | W10: FALSE
A11: 10 | B11: 骆思玥 | C11: scratch | D11: =IF(VLOOKUP($A11,学生考级成绩!$A:$E,4,0)=0,"",VLOOKUP($A11,学生考级成绩!$A:$E,4,0)) -> 二级 | E11: =IF(VLOOKUP($A11,学生考级成绩!$A:$E,5,0)=0,"",VLOOKUP($A11,学生考级成绩!$A:$E,5,0)) | F11: =IF(VLOOKUP($A11,学生考级成绩!$A:$F,6,0)=0,"",VLOOKUP($A11,学生考级成绩!$A:$F,6,0)) | G11: 45753 | H11: 12 | I11: =H11*100 -> 1200 | J11: =G11+H11*7 -> 45837 | K11: TRUE | L11: 12 | M11: =IF(K11=TRUE,L11*100,0) -> 1200 | N11: =IF(K11=TRUE,J11+L11*7,"") -> 45921 | O11: TRUE | P11: 12 | Q11: =IF(O11=TRUE,P11*100,0) -> 1200 | R11: =IF(O11=TRUE,N11+P11*7,"") -> 46005 | S11: TRUE | T11: 12 | U11: =IF(S11=TRUE,T11*100,0) -> 1200 | V11: =IF(S11=TRUE,R11+T11*7,"") -> 46089 | W11: FALSE
A12: 11 | B12: 黄奕凡 | C12: scratch | D12: =IF(VLOOKUP($A12,学生考级成绩!$A:$E,4,0)=0,"",VLOOKUP($A12,学生考级成绩!$A:$E,4,0)) -> 一级 | E12: =IF(VLOOKUP($A12,学生考级成绩!$A:$E,5,0)=0,"",VLOOKUP($A12,学生考级成绩!$A:$E,5,0)) | F12: =IF(VLOOKUP($A12,学生考级成绩!$A:$F,6,0)=0,"",VLOOKUP($A12,学生考级成绩!$A:$F,6,0)) | G12: 45801 | H12: 24 | I12: =H12*100 -> 2400 | J12: =G12+H12*7 -> 45969 | K12: TRUE | L12: 12 | M12: =IF(K12=TRUE,L12*100,0) -> 1200 | N12: =IF(K12=TRUE,J12+L12*7,"") -> 46053 | O12: FALSE | Q12: =IF(O12=TRUE,P12*100,0) -> 0 | R12: =IF(O12=TRUE,N12+P12*7,"") | S12: FALSE | U12: =IF(S12=TRUE,T12*100,0) -> 0 | V12: =IF(S12=TRUE,R12+T12*7,"") | W12: FALSE
A13: 12 | B13: 王语桐 | C13: scratch | D13: =IF(VLOOKUP($A13,学生考级成绩!$A:$E,4,0)=0,"",VLOOKUP($A13,学生考级成绩!$A:$E,4,0)) -> 三级 | E13: =IF(VLOOKUP($A13,学生考级成绩!$A:$E,5,0)=0,"",VLOOKUP($A13,学生考级成绩!$A:$E,5,0)) | F13: =IF(VLOOKUP($A13,学生考级成绩!$A:$F,6,0)=0,"",VLOOKUP($A13,学生考级成绩!$A:$F,6,0)) | G13: 45816 | H13: 36 | I13: 3000 | J13: =G13+H13*7 -> 46068 | K13: TRUE | L13: 6 | M13: =IF(K13=TRUE,L13*100,0) -> 600 | N13: =IF(K13=TRUE,J13+L13*7,"") -> 46110 | O13: FALSE | Q13: =IF(O13=TRUE,P13*100,0) -> 0 | R13: =IF(O13=TRUE,N13+P13*7,"") | S13: FALSE | U13: =IF(S13=TRUE,T13*100,0) -> 0 | V13: =IF(S13=TRUE,R13+T13*7,"") | W13: FALSE
A14: 13 | B14: 张欣瑶 | C14: scratch | D14: =IF(VLOOKUP($A14,学生考级成绩!$A:$E,4,0)=0,"",VLOOKUP($A14,学生考级成绩!$A:$E,4,0)) -> 二级 | E14: =IF(VLOOKUP($A14,学生考级成绩!$A:$E,5,0)=0,"",VLOOKUP($A14,学生考级成绩!$A:$E,5,0)) | F14: =IF(VLOOKUP($A14,学生考级成绩!$A:$F,6,0)=0,"",VLOOKUP($A14,学生考级成绩!$A:$F,6,0)) | G14: 45829 | H14: 24 | I14: =H14*100 -> 2400 | J14: =G14+H14*7 -> 45997 | K14: TRUE | L14: 12 | M14: =IF(K14=TRUE,L14*100,0) -> 1200 | N14: =IF(K14=TRUE,J14+L14*7,"") -> 46081 | O14: FALSE | Q14: =IF(O14=TRUE,P14*100,0) -> 0 | R14: =IF(O14=TRUE,N14+P14*7,"") | S14: FALSE | U14: =IF(S14=TRUE,T14*100,0) -> 0 | V14: =IF(S14=TRUE,R14+T14*7,"") | W14: FALSE
A15: 14 | B15: 孙靖宇 | C15: Python | D15: =IF(VLOOKUP($A15,学生考级成绩!$A:$E,4,0)=0,"",VLOOKUP($A15,学生考级成绩!$A:$E,4,0)) | E15: =IF(VLOOKUP($A15,学生考级成绩!$A:$E,5,0)=0,"",VLOOKUP($A15,学生考级成绩!$A:$E,5,0)) -> 三级 | F15: =IF(VLOOKUP($A15,学生考级成绩!$A:$F,6,0)=0,"",VLOOKUP($A15,学生考级成绩!$A:$F,6,0)) | G15: 45837 | H15: 12 | I15: =H15*100 -> 1200 | J15: =G15+H15*7 -> 45921 | K15: TRUE | L15: 12 | M15: =IF(K15=TRUE,L15*100,0) -> 1200 | N15: =IF(K15=TRUE,J15+L15*7,"") -> 46005 | O15: TRUE | P15: 12 | Q15: =IF(O15=TRUE,P15*100,0) -> 1200 | R15: =IF(O15=TRUE,N15+P15*7,"") -> 46089 | S15: FALSE | U15: =IF(S15=TRUE,T15*100,0) -> 0 | V15: =IF(S15=TRUE,R15+T15*7,"") | W15: FALSE
A16: 15 | B16: 马睿辰 | C16: Python | D16: =IF(VLOOKUP($A16,学生考级成绩!$A:$E,4,0)=0,"",VLOOKUP($A16,学生考级成绩!$A:$E,4,0)) | E16: =IF(VLOOKUP($A16,学生考级成绩!$A:$E,5,0)=0,"",VLOOKUP($A16,学生考级成绩!$A:$E,5,0)) -> 二级 | F16: =IF(VLOOKUP($A16,学生考级成绩!$A:$F,6,0)=0,"",VLOOKUP($A16,学生考级成绩!$A:$F,6,0)) | G16: 45844 | H16: 12 | I16: =H16*100 -> 1200 | J16: =G16+H16*7 -> 45928 | K16: TRUE | L16: 12 | M16: =IF(K16=TRUE,L16*100,0) -> 1200 | N16: =IF(K16=TRUE,J16+L16*7,"") -> 46012 | O16: TRUE | P16: 12 | Q16: =IF(O16=TRUE,P16*100,0) -> 1200 | R16: =IF(O16=TRUE,N16+P16*7,"") -> 46096 | S16: FALSE | U16: =IF(S16=TRUE,T16*100,0) -> 0 | V16: =IF(S16=TRUE,R16+T16*7,"") | W16: FALSE
